Workbook

Sheet Início
B1: 🏠 Início | D1: 📊 Painel Geral | G1: 👤 Painel Pessoal | I1: 💼 Painel Negócio | K1: ⚙ Config
B2: PESSOAL | D2: 📝 Lançamentos | G2: 💳 Orçamento | I2: 📅 Resumo anual | K2: 🎯 Metas
B3: NEGÓCIO | D3: 📝 Lançamentos | F3: 🤝 Clientes | H3: 💰 Recebimentos | J3: 🧾 Impostos | L3: 📈 Fluxo de Caixa
B5: Finanças em Dia — Autônomo & MEI
B6: Controle financeiro pessoal + negócio • Excel e Google Sheets
B7: Bem-vindo(a)! Esta planilha organiza suas finanças do jeito mais simples: você só LANÇA os valores e todo o resto — resumos, gráficos, alertas e metas — é calculado automaticamente. Aqui, vida pessoal e negócio ficam separados, com controle de clientes, recebimentos, impostos (DAS do MEI) e fluxo de caixa.
B9: 🚀 COMECE EM 5 MINUTOS
B10: 1 | C10: Em ⚙ Config: confira o ANO, escreva seu nome/negócio e renomeie as categorias, se quiser.
B11: 2 | C11: Em 💳 Orçamento Pessoal e 🎯 Metas: informe quanto pretende gastar e quais objetivos quer alcançar.
B12: 3 | C12: Em 🧾 Impostos: escolha seu regime (MEI, Simples ou outro) e confira o valor do DAS.
B13: 4 | C13: Cadastre seus 🤝 Clientes e registre cada cobrança em 💰 Recebimentos (com vencimento e data de pagamento).
B14: 5 | C14: No dia a dia: lance gastos em 📝 Lançamentos (pessoal e negócio). Depois é só abrir os 📊 Painéis!
B16: 🗺 MAPA DA PLANILHA — clique no botão para navegar
B17: 📊 Painel Geral | E17: Visão consolidada: caixa pessoal + negócio, resultado mensal e cobertura do custo de vida.
B18: 👤 Painel Pessoal | E18: Entradas, saídas, saldo, taxa de poupança, categorias, metas e alertas da vida pessoal.
B19: 💼 Painel Negócio | E19: Receita, despesas, lucro, top clientes, cobranças em atraso e limite do MEI.
B20: 📝 Lanç. Pessoal | E20: Registro de entradas e saídas pessoais (tipo automático pela categoria).
B21: 💳 Orçamento Pessoal | E21: Planejado × realizado por categoria, com barras de progresso e alertas.
B22: 📅 Resumo Pessoal | E22: Quadro anual mês a mês por categoria, com mapa de calor.
B23: 🎯 Metas | E23: Objetivos de economia, aporte mensal necessário e reserva de emergência.
B24: 📝 Lanç. Negócio | E24: Despesas e receitas avulsas do negócio (separadas das pessoais).
B25: 🤝 Clientes | E25: Cadastro de clientes com faturamento, recebido, a receber e inadimplência.
B26: 💰 Recebimentos | E26: Cobranças emitidas: vencimento, data de pagamento e status automático.
B27: 🧾 Impostos | E27: DAS do MEI (ou % do Simples), vencimentos, pagamentos e limite anual.
B28: 📈 Fluxo de Caixa | E28: Caixa do negócio mês a mês: realizado e projetado, com saldo acumulado.
B29: ⚙ Config | E29: Ano, nome, categorias, formas de pagamento e metas gerais.
B31: 🎨 LEGENDA DE CORES
B32: Você preenche | D32: Fórmula (automático) | F32: Positivo / bom | H32: Atenção | J32: Negativo / alerta | L32: Informação
B34: 💡 DICAS IMPORTANTES
B35: • Google Sheets: envie o arquivo .xlsx para o Google Drive e abra com o Google Planilhas (ou Arquivo ▸ Importar). Os menus, gráficos, listas suspensas e cores funcionam igualmente.
B36: • Digite sempre valores POSITIVOS. Se a categoria for de entrada, o valor soma; se for de saída, subtrai — o tipo é automático.
B37: • Retirada do negócio: lance a saída 'Pró-labore / Retirada' em Lanç. Negócio e a entrada 'Pró-labore' em Lanç. Pessoal. Receitas de clientes: lance só em Recebimentos (não duplique).
B38: • Para começar um novo ano: salve uma cópia do arquivo, apague os lançamentos (colunas amarelas) e mude o ano em Config.
B39: • Não insira/apague linhas dentro das tabelas de fórmulas. Para ver mais lançamentos, use os filtros do cabeçalho; há espaço para 1500 linhas.
B40: • Cada aba tem botões de navegação no topo. Se algo parecer estranho, confira a faixa de VERIFICAÇÃO no topo de Lançamentos.
B41: • Os valores do DAS/MEI e o limite anual são parâmetros editáveis na aba Impostos — confira sempre a legislação vigente no Portal do Simples Nacional. Esta planilha organiza, mas não substitui um contador.
B43: Planilha educativa de organização financeira. Valores e exemplos são fictícios.

Sheet Painel Geral
B1: 🏠 Início | D1: 📊 Painel Geral | G1: 👤 Painel Pessoal | I1: 💼 Painel Negócio | K1: ⚙ Config
B2: PESSOAL | D2: 📝 Lançamentos | G2: 💳 Orçamento | I2: 📅 Resumo anual | K2: 🎯 Metas
B3: NEGÓCIO | D3: 📝 Lançamentos | F3: 🤝 Clientes | H3: 💰 Recebimentos | J3: 🧾 Impostos | L3: 📈 Fluxo de Caixa
B5: ="📊 Painel Geral — "&'Config'!$C$10 -> 📊 Painel Geral — Meu Controle Financeiro
B6: Visão consolidada: vida pessoal + negócio. O negócio sustenta o seu custo de vida?
B7: 📅 Mês de análise | D7: Setembro | G7: Ano de referência | I7: ='Config'!$C$8 -> 2026 | J7: ← escolha o mês; a aba Config guarda ano e metas
B9: SALDO PESSOAL ACUMULADO | D9: CAIXA DO NEGÓCIO | F9: CAIXA TOTAL | H9: RESULTADO PESSOAL (MÊS) | J9: LUCRO DO NEGÓCIO (MÊS) | L9: PRÓ-LABORE ÷ GASTOS PESSOAIS
B10: =INDEX('Resumo Pessoal'!$C$38:$N$38,'Dados'!$C$41) -> 3592.59 | D10: =INDEX('Fluxo de Caixa'!$C$29:$N$29,'Dados'!$C$41) -> 4182.18 | F10: =INDEX('Resumo Pessoal'!$C$38:$N$38,'Dados'!$C$41)+INDEX('Fluxo de Caixa'!$C$29:$N$29,'Dados'!$C$41) -> 7774.77 | H10: =INDEX('Dados'!$C$115:$N$115,'Dados'!$C$41) -> 560.05 | J10: =INDEX('Dados'!$C$110:$N$110,'Dados'!$C$41) -> 4710.68 | L10: =IF(INDEX('Dados'!$C$117:$N$117,'Dados'!$C$41)=0,0,INDEX('Dados'!$C$116:$N$116,'Dados'!$C$41)/INDEX('Dados'!$C$117:$N$117,'Dados'!$C$41)) -> 1.1270174
B11: pessoal, no fim do mês | D11: =IF('Dados'!$C$41<='Dados'!$C$10,"realizado","projetado") -> realizado | F11: pessoal + negócio | H11: entradas − saídas pessoais | J11: receita − despesas − impostos | L11: cobertura do custo de vida
B45: 🔔 ALERTAS E INSIGHTS
B46: ='Impostos'!$H$13 -> ✓ Dentro do limite anual do MEI.
B47: =IF(SUM('Recebimentos'!$L$11:$L$1010)=0,"✓ Nenhuma cobrança em atraso.","⚠ Você tem R$ "&FIXED(SUM('Recebimentos'!$L$11:$L$1010),2)&" em cobranças atrasadas — veja a aba Recebimentos.") -> ⚠ Você tem R$ 4,430.00 em cobranças atrasadas — veja a aba Recebimentos.
B48: =IF('Dados'!$C$42=99,"✓ O caixa do negócio permanece positivo no ano (incluindo a projeção).","⚠ O caixa do negócio projetado fica negativo a partir de "&INDEX('Config'!$K$8:$K$19,'Dados'!$C$42)&".") -> ✓ O caixa do negócio permanece positivo no ano (incluindo a projeção).
B49: =IF(INDEX('Dados'!$C$117:$N$117,'Dados'!$C$41)=0,"ℹ Registre os gastos pessoais do mês para medir a cobertura do custo de vida.",IF(IF(INDEX('Dados'!$C$117:$N$117,'Dados'!$C$41)=0,0,INDEX('Dados'!$C$116:$N$116,'Dados'!$C$41)/INDEX('Dados'!$C$117:$N$117,'Dados'!$C$41))>=1,"✓ O pró-labore do mês cobre "&TEXT(IF(INDEX('Dados'!$C$117:$N$117,'Dados'!$C$41)=0,0,INDEX('Dados'!$C$116:$N$116,'Dados'!$C$41)/INDEX('Dados'!$C$117:$N$117,'Dados'!$C$41)),"0%")&" dos seus gastos pessoais.","⚠ O pró-labore cobre só "&TEXT(IF(INDEX('Dados'!$C$117:$N$117,'Dados'!$C$41)=0,0,INDEX('Dados'!$C$116:$N$116,'Dados'!$C$41)/INDEX('Dados'!$C$117:$N$117,'Dados'!$C$41)),"0%")&" dos gastos pessoais do mês — o restante saiu de reservas.")) -> ✓ O pró-labore do mês cobre 113% dos seus gastos pessoais.

Sheet Painel Pessoal
B1: 🏠 Início | D1: 📊 Painel Geral | G1: 👤 Painel Pessoal | I1: 💼 Painel Negócio | K1: ⚙ Config
B2: PESSOAL | D2: 📝 Lançamentos | G2: 💳 Orçamento | I2: 📅 Resumo anual | K2: 🎯 Metas
B3: NEGÓCIO | D3: 📝 Lançamentos | F3: 🤝 Clientes | H3: 💰 Recebimentos | J3: 🧾 Impostos | L3: 📈 Fluxo de Caixa
B5: ="👤 Painel Pessoal — "&'Config'!$C$10 -> 👤 Painel Pessoal — Meu Controle Financeiro
B6: Escolha o mês no menu suspenso: cartões, gráficos e alertas se atualizam sozinhos.
B7: 📅 Mês de análise | D7: Setembro | G7: Ano de referência | I7: ='Config'!$C$8 -> 2026 | J7: ← o ano e a meta de poupança ficam na aba Config
B9: ENTRADAS DO MÊS | D9: SAÍDAS DO MÊS | F9: SALDO DO MÊS | H9: TAXA DE POUPANÇA | J9: SALDO ACUMULADO | L9: MAIOR GASTO DO MÊS
B10: =INDEX('Resumo Pessoal'!$C$18:$N$18,'Dados'!$C$8) -> 4552.89 | D10: =INDEX('Resumo Pessoal'!$C$36:$N$36,'Dados'!$C$8) -> 3992.84 | F10: =INDEX('Resumo Pessoal'!$C$18:$N$18,'Dados'!$C$8)-INDEX('Resumo Pessoal'!$C$36:$N$36,'Dados'!$C$8) -> 560.05 | H10: =IF(INDEX('Resumo Pessoal'!$C$18:$N$18,'Dados'!$C$8)=0,0,INDEX('Resumo Pessoal'!$C$39:$N$39,'Dados'!$C$8)) -> 0.25479421 | J10: =INDEX('Resumo Pessoal'!$C$38:$N$38,'Dados'!$C$8) -> 3592.59 | L10: ='Dados'!$J$18 -> Moradia
B11: =IF('Dados'!$C$8=1,"—",IF(INDEX('Resumo Pessoal'!$C$18:$N$18,'Dados'!$C$8-1)=0,"—",IF(INDEX('Resumo Pessoal'!$C$18:$N$18,'Dados'!$C$8)>=INDEX('Resumo Pessoal'!$C$18:$N$18,'Dados'!$C$8-1),"▲ ","▼ ")&TEXT(ABS(INDEX('Resumo Pessoal'!$C$18:$N$18,'Dados'!$C$8)/INDEX('Resumo Pessoal'!$C$18:$N$18,'Dados'!$C$8-1)-1),"0%")&" vs mês anterior")) -> ▲ 0% vs mês anterior | D11: =IF('Dados'!$C$8=1,"—",IF(INDEX('Resumo Pessoal'!$C$36:$N$36,'Dados'!$C$8-1)=0,"—",IF(INDEX('Resumo Pessoal'!$C$36:$N$36,'Dados'!$C$8)>=INDEX('Resumo Pessoal'!$C$36:$N$36,'Dados'!$C$8-1),"▲ ","▼ ")&TEXT(ABS(INDEX('Resumo Pessoal'!$C$36:$N$36,'Dados'!$C$8)/INDEX('Resumo Pessoal'!$C$36:$N$36,'Dados'!$C$8-1)-1),"0%")&" vs mês anterior")) -> ▼ 14% vs mês anterior | F11: =IF(INDEX('Resumo Pessoal'!$C$18:$N$18,'Dados'!$C$8)-INDEX('Resumo Pessoal'!$C$36:$N$36,'Dados'!$C$8)>=0,"Sobrou dinheiro ✓","Gastou mais do que ganhou") -> Sobrou dinheiro ✓ | H11: ="Meta: "&TEXT('Config'!$C$11,"0%") -> Meta: 20% | J11: no ano, até o mês escolhido | L11: ='Dados'!$K$18 -> 1100
B45: 🎯 METAS DE ECONOMIA
B46: Meta | E46: Guardado | G46: Valor alvo | I46: % | J46: Progresso | M46: Situação
B47: =IF('Metas'!$B$8="","",'Metas'!$B$8) -> Reserva de emergência | E47: =IF('Metas'!$B$8="","",'Metas'!$G$8) -> 8700 | G47: =IF('Metas'!$B$8="","",'Metas'!$C$8) -> 24000 | I47: =IF('Metas'!$H$8="","",'Metas'!$H$8) -> 0.3625 | J47: =IF('Metas'!$I$8="","",'Metas'!$I$8) -> ███████ | M47: =IF('Metas'!$B$8="","",'Metas'!$M$8) -> ● No prazo
B48: =IF('Metas'!$B$9="","",'Metas'!$B$9) -> Reserva para impostos | E48: =IF('Metas'!$B$9="","",'Metas'!$G$9) -> 1350 | G48: =IF('Metas'!$B$9="","",'Metas'!$C$9) -> 4000 | I48: =IF('Metas'!$H$9="","",'Metas'!$H$9) -> 0.3375 | J48: =IF('Metas'!$I$9="","",'Metas'!$I$9) -> ███████ | M48: =IF('Metas'!$B$9="","",'Metas'!$M$9) -> ● No prazo
B49: =IF('Metas'!$B$10="","",'Metas'!$B$10) -> Viagem de férias | E49: =IF('Metas'!$B$10="","",'Metas'!$G$10) -> 1400 | G49: =IF('Metas'!$B$10="","",'Metas'!$C$10) -> 6000 | I49: =IF('Metas'!$H$10="","",'Metas'!$H$10) -> 0.23333333 | J49: =IF('Metas'!$I$10="","",'Metas'!$I$10) -> █████ | M49: =IF('Metas'!$B$10="","",'Metas'!$M$10) -> ● No prazo
B50: =IF('Metas'!$B$11="","",'Metas'!$B$11) | E50: =IF('Metas'!$B$11="","",'Metas'!$G$11) | G50: =IF('Metas'!$B$11="","",'Metas'!$C$11) | I50: =IF('Metas'!$H$11="","",'Metas'!$H$11) | J50: =IF('Metas'!$I$11="","",'Metas'!$I$11) | M50: =IF('Metas'!$B$11="","",'Metas'!$M$11)
B51: =IF('Metas'!$B$12="","",'Metas'!$B$12) | E51: =IF('Metas'!$B$12="","",'Metas'!$G$12) | G51: =IF('Metas'!$B$12="","",'Metas'!$C$12) | I51: =IF('Metas'!$H$12="","",'Metas'!$H$12) | J51: =IF('Metas'!$I$12="","",'Metas'!$I$12) | M51: =IF('Metas'!$B$12="","",'Metas'!$M$12)
B53: Veja todas as metas e o simulador de aportes na aba Metas.
B54: 🔔 ALERTAS E INSIGHTS DO MÊS
B55: =IF(AND(INDEX('Resumo Pessoal'!$C$18:$N$18,'Dados'!$C$8)=0,INDEX('Resumo Pessoal'!$C$36:$N$36,'Dados'!$C$8)=0),"ℹ Ainda não há lançamentos neste mês.",IF((INDEX('Resumo Pessoal'!$C$18:$N$18,'Dados'!$C$8)-INDEX('Resumo Pessoal'!$C$36:$N$36,'Dados'!$C$8))<0,"⚠ Você gastou R$ "&FIXED(-(INDEX('Resumo Pessoal'!$C$18:$N$18,'Dados'!$C$8)-INDEX('Resumo Pessoal'!$C$36:$N$36,'Dados'!$C$8)),2)&" a mais do que ganhou neste mês.","✓ Mês no azul: sobraram R$ "&FIXED((INDEX('Resumo Pessoal'!$C$18:$N$18,'Dados'!$C$8)-INDEX('Resumo Pessoal'!$C$36:$N$36,'Dados'!$C$8)),2)&" depois de todas as saídas.")) -> ✓ Mês no azul: sobraram R$ 560.05 depois de todas as saídas.
B56: =IF('Orçamento Pessoal'!$C$28=0,"ℹ Defina o orçamento por categoria na aba Orçamento para receber alertas de gastos.",IF('Dados'!$C$13=0,"✓ Nenhuma categoria acima do orçamento neste mês.","⚠ "&'Dados'!$C$13&" categoria(s) acima do orçamento planejado — veja a aba Orçamento.")) -> ⚠ 2 categoria(s) acima do orçamento planejado — veja a aba Orçamento.
B57: =IF(INDEX('Resumo Pessoal'!$C$18:$N$18,'Dados'!$C$8)=0,"ℹ Registre suas entradas do mês para calcular a taxa de poupança.",IF(INDEX('Resumo Pessoal'!$C$39:$N$39,'Dados'!$C$8)>='Config'!$C$11,"✓ Meta de poupança atingida: "&TEXT(INDEX('Resumo Pessoal'!$C$39:$N$39,'Dados'!$C$8),"0%")&" (meta "&TEXT('Config'!$C$11,"0%")&").","⚠ Taxa de poupança de "&TEXT(INDEX('Resumo Pessoal'!$C$39:$N$39,'Dados'!$C$8),"0%")&", abaixo da meta de "&TEXT('Config'!$C$11,"0%")&".")) -> ✓ Meta de poupança atingida: 25% (meta 20%).

Sheet Painel Negócio
B1: 🏠 Início | D1: 📊 Painel Geral | G1: 👤 Painel Pessoal | I1: 💼 Painel Negócio | K1: ⚙ Config
B2: PESSOAL | D2: 📝 Lançamentos | G2: 💳 Orçamento | I2: 📅 Resumo anual | K2: 🎯 Metas
B3: NEGÓCIO | D3: 📝 Lançamentos | F3: 🤝 Clientes | H3: 💰 Recebimentos | J3: 🧾 Impostos | L3: 📈 Fluxo de Caixa
B5: ="💼 Painel Negócio — "&'Config'!$C$13 -> 💼 Painel Negócio — Estúdio Exemplo
B6: Receita, despesas, lucro, clientes, cobranças em atraso e limite do MEI — tudo do mês escolhido.
B7: 📅 Mês de análise | D7: Setembro | G7: Ano de referência | I7: ='Config'!$C$8 -> 2026 | J7: ← escolha o mês; os valores só aparecem até o mês de referência (hoje)
B9: RECEITA DO MÊS | D9: DESPESAS + IMPOSTOS | F9: LUCRO DE CAIXA | H9: A RECEBER (EM ABERTO) | J9: LIMITE DO MEI USADO | L9: IMPOSTO DO MÊS (DAS)
B10: =INDEX('Dados'!$C$108:$N$108,'Dados'!$C$40) -> 6266.84 | D10: =INDEX('Dados'!$C$109:$N$109,'Dados'!$C$40) -> 1556.16 | F10: =INDEX('Dados'!$C$110:$N$110,'Dados'!$C$40) -> 4710.68 | H10: =SUM('Recebimentos'!$K$11:$K$1010) -> 6730 | J10: =IF('Impostos'!$E$8<>"MEI","n/a",'Impostos'!$L$10) -> 0.69763691 | L10: =INDEX('Impostos'!$D$23:$D$34,'Dados'!$C$40) -> 86.05
B11: =IF('Dados'!$C$40=1,"—",IF(INDEX('Dados'!$C$108:$N$108,'Dados'!$C$40-1)=0,"—",IF(INDEX('Dados'!$C$108:$N$108,'Dados'!$C$40)>=INDEX('Dados'!$C$108:$N$108,'Dados'!$C$40-1),"▲ ","▼ ")&TEXT(ABS(INDEX('Dados'!$C$108:$N$108,'Dados'!$C$40)/INDEX('Dados'!$C$108:$N$108,'Dados'!$C$40-1)-1),"0%")&" vs mês anterior")) -> ▼ 14% vs mês anterior | D11: =IF('Dados'!$C$40=1,"—",IF(INDEX('Dados'!$C$109:$N$109,'Dados'!$C$40-1)=0,"—",IF(INDEX('Dados'!$C$109:$N$109,'Dados'!$C$40)>=INDEX('Dados'!$C$109:$N$109,'Dados'!$C$40-1),"▲ ","▼ ")&TEXT(ABS(INDEX('Dados'!$C$109:$N$109,'Dados'!$C$40)/INDEX('Dados'!$C$109:$N$109,'Dados'!$C$40-1)-1),"0%")&" vs mês anterior")) -> ▲ 2% vs mês anterior | F11: =IF(INDEX('Dados'!$C$108:$N$108,'Dados'!$C$40)=0,"—","Margem de "&TEXT(INDEX('Dados'!$C$110:$N$110,'Dados'!$C$40)/INDEX('Dados'!$C$108:$N$108,'Dados'!$C$40),"0%")) -> Margem de 75% | H11: =SUM('Recebimentos'!$L$11:$L$1010) -> 4430 | J11: =IF('Impostos'!$E$8<>"MEI","regime sem limite MEI","Projeção: "&TEXT('Impostos'!$L$12,"0%")&" do limite") -> Projeção: 93% do limite | L11: =INDEX('Impostos'!$I$23:$I$34,'Dados'!$C$40) -> A pagar
B45: ⏰ COBRANÇAS EM ATRASO (as 5 mais antigas)
B46: Cliente | E46: Descrição | I46: Vencimento | K46: Dias | L46: Valor
B47: =IF('Dados'!$I$100>0,'Dados'!$J$100,IF('Dados'!$I$100=0,"✓ Nenhuma cobrança em atraso","")) -> Café do Centro | E47: ='Dados'!$K$100 -> Reimpressão de materiais | I47: ='Dados'!$L$100 -> 46261 | K47: ='Dados'!$M$100 -> 34 | L47: ='Dados'!$N$100 -> 480
B48: =IF('Dados'!$I$101>0,'Dados'!$J$101,"") -> Studio Aurora | E48: ='Dados'!$K$101 -> Gestão de redes sociais – 09/2026 | I48: ='Dados'!$L$101 -> 46278 | K48: ='Dados'!$M$101 -> 17 | L48: ='Dados'!$N$101 -> 1800
B49: =IF('Dados'!$I$102>0,'Dados'!$J$102,"") -> Clínica Vida Plena | E49: ='Dados'!$K$102 -> Pacote de conteúdo mensal – 09/2026 | I49: ='Dados'!$L$102 -> 46280 | K49: ='Dados'!$M$102 -> 15 | L49: ='Dados'!$N$102 -> 1500
B50: =IF('Dados'!$I$103>0,'Dados'!$J$103,"") -> Padaria Dois Irmãos | E50: ='Dados'!$K$103 -> Materiais e cardápio – 09/2026 | I50: ='Dados'!$L$103 -> 46283 | K50: ='Dados'!$M$103 -> 12 | L50: ='Dados'!$N$103 -> 650
B51: =IF('Dados'!$I$104>0,'Dados'!$J$104,"") | E51: ='Dados'!$K$104 | I51: ='Dados'!$L$104 | K51: ='Dados'!$M$104 | L51: ='Dados'!$N$104
B53: 🔔 ALERTAS E INSIGHTS
B54: ='Impostos'!$H$13 -> ✓ Dentro do limite anual do MEI.
B55: =IF('Clientes'!$B$40="","ℹ Registre recebimentos para analisar a concentração de clientes.",'Clientes'!$B$40) -> ✓ Receita bem distribuída entre clientes (maior cliente: 26%).
B56: =IF('Dados'!$C$42=99,"✓ O caixa do negócio não fica negativo em nenhum mês do ano (incluindo a projeção).","⚠ O caixa projetado fica negativo a partir de "&INDEX('Config'!$K$8:$K$19,'Dados'!$C$42)&". Antecipe recebimentos ou reduza despesas.") -> ✓ O caixa do negócio não fica negativo em nenhum mês do ano (incluindo a projeção).

Sheet Lanç. Pessoal
B1: 🏠 Início | D1: 📊 Painel Geral | E1: 👤 Painel Pessoal | G1: 💼 Painel Negócio | I1: ⚙ Config
B2: PESSOAL | D2: 📝 Lançamentos | E2: 💳 Orçamento | G2: 📅 Resumo anual | I2: 🎯 Metas
B3: NEGÓCIO | C3: 📝 Lançamentos | D3: 🤝 Clientes | E3: 💰 Recebimentos | G3: 🧾 Impostos | I3: 📈 Fluxo de Caixa
B5: 📝 Lançamentos pessoais
B6: Preencha as colunas amarelas. Valor sempre positivo; o Tipo (Entrada/Saída) é automático pela categoria.
B7: ENTRADAS NO ANO | D7: SAÍDAS NO ANO | E7: SALDO DO ANO | G7: VERIFICAÇÃO AUTOMÁTICA
B8: =SUMIFS('Lanç. Pessoal'!$F$11:$F$1510,'Lanç. Pessoal'!$G$11:$G$1510,"Entrada",'Lanç. Pessoal'!$B$11:$B$1510,">="&DATE('Config'!$C$8,1,1),'Lanç. Pessoal'!$B$11:$B$1510,"<"&DATE('Config'!$C$8+1,1,1)) -> 41725.12 | D8: =SUMIFS('Lanç. Pessoal'!$F$11:$F$1510,'Lanç. Pessoal'!$G$11:$G$1510,"Saída",'Lanç. Pessoal'!$B$11:$B$1510,">="&DATE('Config'!$C$8,1,1),'Lanç. Pessoal'!$B$11:$B$1510,"<"&DATE('Config'!$C$8+1,1,1)) -> 40632.53 | E8: =B8-D8 -> 1092.59 | G8: =IF(SUMPRODUCT(('Lanç. Pessoal'!$F$11:$F$1510>0)*('Lanç. Pessoal'!$D$11:$D$1510=""))>0,"⚠ "&SUMPRODUCT(('Lanç. Pessoal'!$F$11:$F$1510>0)*('Lanç. Pessoal'!$D$11:$D$1510=""))&" lançamento(s) sem categoria — não entram nos painéis",IF(COUNTIF('Lanç. Pessoal'!$G$11:$G$1510,"Verificar")>0,"⚠ "&COUNTIF('Lanç. Pessoal'!$G$11:$G$1510,"Verificar")&" lançamento(s) com categoria inválida (coluna Tipo = Verificar)",IF((COUNT('Lanç. Pessoal'!$F$11:$F$1510)-COUNTIFS('Lanç. Pessoal'!$B$11:$B$1510,">="&DATE('Config'!$C$8,1,1),'Lanç. Pessoal'!$B$11:$B$1510,"<"&DATE('Config'!$C$8+1,1,1),'Lanç. Pessoal'!$F$11:$F$1510,">0"))>0,"⚠ "&(COUNT('Lanç. Pessoal'!$F$11:$F$1510)-COUNTIFS('Lanç. Pessoal'!$B$11:$B$1510,">="&DATE('Config'!$C$8,1,1),'Lanç. Pessoal'!$B$11:$B$1510,"<"&DATE('Config'!$C$8+1,1,1),'Lanç. Pessoal'!$F$11:$F$1510,">0"))&" lançamento(s) sem data ou fora de "&'Config'!$C$8&" — não entram nos painéis","✓ Tudo certo: "&COUNT('Lanç. Pessoal'!$F$11:$F$1510)&" lançamento(s) registrados"))) -> ✓ Tudo certo: 321 lançamento(s) registrados
B10: Data | C10: Descrição | D10: Categoria | E10: Forma de pagamento | F10: Valor (R$) | G10: Tipo | H10: Meta (opcional) | I10: Observação
B11: 46025 | C11: Academia | D11: Cuidados pessoais | E11: Débito automático | F11: 119.9 | G11: =IF($D11="","",IF(COUNTIF('Config'!$E$8:$E$15,$D11)>0,"Entrada",IF(COUNTIF('Config'!$G$8:$G$23,$D11)>0,"Saída","Verificar"))) -> Saída
B12: 46025 | C12: Supermercado | D12: Alimentação | E12: Cartão de crédito | F12: 178.02 | G12: =IF($D12="","",IF(COUNTIF('Config'!$E$8:$E$15,$D12)>0,"Entrada",IF(COUNTIF('Config'!$G$8:$G$23,$D12)>0,"Saída","Verificar"))) -> Saída
B13: 46026 | C13: Combustível | D13: Transporte | E13: Cartão de crédito | F13: 194.3 | G13: =IF($D13="","",IF(COUNTIF('Config'!$E$8:$E$15,$D13)>0,"Entrada",IF(COUNTIF('Config'!$G$8:$G$23,$D13)>0,"Saída","Verificar"))) -> Saída
B14: 46027 | C14: Pró-labore do mês | D14: Pró-labore / Retirada do negócio | E14: Transferência | F14: 4500 | G14: =IF($D14="","",IF(COUNTIF('Config'!$E$8:$E$15,$D14)>0,"Entrada",IF(COUNTIF('Config'!$G$8:$G$23,$D14)>0,"Saída","Verificar"))) -> Entrada
B15: 46028 | C15: Aporte reserva de emergência | D15: Reserva e Metas | E15: Pix | F15: 300 | G15: =IF($D15="","",IF(COUNTIF('Config'!$E$8:$E$15,$D15)>0,"Entrada",IF(COUNTIF('Config'!$G$8:$G$23,$D15)>0,"Saída","Verificar"))) -> Saída | H15: Reserva de emergência
B16: 46028 | C16: Aporte reserva para impostos | D16: Reserva e Metas | E16: Pix | F16: 150 | G16: =IF($D16="","",IF(COUNTIF('Config'!$E$8:$E$15,$D16)>0,"Entrada",IF(COUNTIF('Config'!$G$8:$G$23,$D16)>0,"Saída","Verificar"))) -> Saída | H16: Reserva para impostos
B17: 46028 | C17: Armazenamento na nuvem | D17: Assinaturas | E17: Cartão de crédito | F17: 9.9 | G17: =IF($D17="","",IF(COUNTIF('Config'!$E$8:$E$15,$D17)>0,"Entrada",IF(COUNTIF('Config'!$G$8:$G$23,$D17)>0,"Saída","Verificar"))) -> Saída
B18: 46028 | C18: Netflix | D18: Assinaturas | E18: Cartão de crédito | F18: 55.9 | G18: =IF($D18="","",IF(COUNTIF('Config'!$E$8:$E$15,$D18)>0,"Entrada",IF(COUNTIF('Config'!$G$8:$G$23,$D18)>0,"Saída","Verificar"))) -> Saída
B19: 46028 | C19: Padaria / hortifruti | D19: Alimentação | E19: Pix | F19: 31.96 | G19: =IF($D19="","",IF(COUNTIF('Config'!$E$8:$E$15,$D19)>0,"Entrada",IF(COUNTIF('Config'!$G$8:$G$23,$D19)>0,"Saída","Verificar"))) -> Saída
B20: 46028 | C20: Spotify | D20: Assinaturas | E20: Cartão de crédito | F20: 21.9 | G20: =IF($D20="","",IF(COUNTIF('Config'!$E$8:$E$15,$D20)>0,"Entrada",IF(COUNTIF('Config'!$G$8:$G$23,$D20)>0,"Saída","Verificar"))) -> Saída
B21: 46029 | C21: App de transporte | D21: Transporte | E21: Cartão de crédito | F21: 32.68 | G21: =IF($D21="","",IF(COUNTIF('Config'!$E$8:$E$15,$D21)>0,"Entrada",IF(COUNTIF('Config'!$G$8:$G$23,$D21)>0,"Saída","Verificar"))) -> Saída
B22: 46030 | C22: Internet fibra | D22: Contas da casa | E22: Débito automático | F22: 119.9 | G22: =IF($D22="","",IF(COUNTIF('Config'!$E$8:$E$15,$D22)>0,"Entrada",IF(COUNTIF('Config'!$G$8:$G$23,$D22)>0,"Saída","Verificar"))) -> Saída
B23: 46030 | C23: Restaurante / bar | D23: Lazer | E23: Cartão de crédito | F23: 54.68 | G23: =IF($D23="","",IF(COUNTIF('Config'!$E$8:$E$15,$D23)>0,"Entrada",IF(COUNTIF('Config'!$G$8:$G$23,$D23)>0,"Saída","Verificar"))) -> Saída
B24: 46031 | C24: Delivery | D24: Alimentação | E24: Cartão de débito | F24: 63.39 | G24: =IF($D24="","",IF(COUNTIF('Config'!$E$8:$E$15,$D24)>0,"Entrada",IF(COUNTIF('Config'!$G$8:$G$23,$D24)>0,"Saída","Verificar"))) -> Saída
B25: 46032 | C25: Aluguel | D25: Moradia | E25: Boleto | F25: 950 | G25: =IF($D25="","",IF(COUNTIF('Config'!$E$8:$E$15,$D25)>0,"Entrada",IF(COUNTIF('Config'!$G$8:$G$23,$D25)>0,"Saída","Verificar"))) -> Saída
B26: 46032 | C26: Condomínio | D26: Moradia | E26: Boleto | F26: 150 | G26: =IF($D26="","",IF(COUNTIF('Config'!$E$8:$E$15,$D26)>0,"Entrada",IF(COUNTIF('Config'!$G$8:$G$23,$D26)>0,"Saída","Verificar"))) -> Saída
B27: 46032 | C27: Plano de saúde | D27: Saúde | E27: Débito automático | F27: 180 | G27: =IF($D27="","",IF(COUNTIF('Config'!$E$8:$E$15,$D27)>0,"Entrada",IF(COUNTIF('Config'!$G$8:$G$23,$D27)>0,"Saída","Verificar"))) -> Saída
B28: 46032 | C28: Supermercado | D28: Alimentação | E28: Cartão de crédito | F28: 163.56 | G28: =IF($D28="","",IF(COUNTIF('Config'!$E$8:$E$15,$D28)>0,"Entrada",IF(COUNTIF('Config'!$G$8:$G$23,$D28)>0,"Saída","Verificar"))) -> Saída
... B47: 46058 | C47: Pró-labore do mês | D47: Pró-labore / Retirada do negócio | E47: Transferência | F47: 4500 | G47: =IF($D47="","",IF(COUNTIF('Config'!$E$8:$E$15,$D47)>0,"Entrada",IF(COUNTIF('Config'!$G$8:$G$23,$D47)>0,"Saída","Verificar"))) -> Entrada
B48: 46059 | C48: Aporte reserva de emergência | D48: Reserva e Metas | E48: Pix | F48: 300 | G48: =IF($D48="","",IF(COUNTIF('Config'!$E$8:$E$15,$D48)>0,"Entrada",IF(COUNTIF('Config'!$G$8:$G$23,$D48)>0,"Saída","Verificar"))) -> Saída | H48: Reserva de emergência
B49: 46059 | C49: Aporte reserva para impostos | D49: Reserva e Metas | E49: Pix | F49: 150 | G49: =IF($D49="","",IF(COUNTIF('Config'!$E$8:$E$15,$D49)>0,"Entrada",IF(COUNTIF('Config'!$G$8:$G$23,$D49)>0,"Saída","Verificar"))) -> Saída | H49: Reserva para impostos
B50: 46059 | C50: Armazenamento na nuvem | D50: Assinaturas | E50: Cartão de crédito | F50: 9.9 | G50: =IF($D50="","",IF(COUNTIF('Config'!$E$8:$E$15,$D50)>0,"Entrada",IF(COUNTIF('Config'!$G$8:$G$23,$D50)>0,"Saída","Verificar"))) -> Saída
B51: 46059 | C51: Netflix | D51: Assinaturas | E51: Cartão de crédito | F51: 55.9 | G51: =IF($D51="","",IF(COUNTIF('Config'!$E$8:$E$15,$D51)>0,"Entrada",IF(COUNTIF('Config'!$G$8:$G$23,$D51)>0,"Saída","Verificar"))) -> Saída
B52: 46059 | C52: Padaria / hortifruti | D52: Alimentação | E52: Pix | F52: 35.75 | G52: =IF($D52="","",IF(COUNTIF('Config'!$E$8:$E$15,$D52)>0,"Entrada",IF(COUNTIF('Config'!$G$8:$G$23,$D52)>0,"Saída","Verificar"))) -> Saída
B53: 46059 | C53: Spotify | D53: Assinaturas | E53: Cartão de crédito | F53: 21.9 | G53: =IF($D53="","",IF(COUNTIF('Config'!$E$8:$E$15,$D53)>0,"Entrada",IF(COUNTIF('Config'!$G$8:$G$23,$D53)>0,"Saída","Verificar"))) -> Saída
B54: 46060 | C54: App de transporte | D54: Transporte | E54: Cartão de crédito | F54: 25.76 | G54: =IF($D54="","",IF(COUNTIF('Config'!$E$8:$E$15,$D54)>0,"Entrada",IF(COUNTIF('Config'!$G$8:$G$23,$D54)>0,"Saída","Verificar"))) -> Saída
B55: 46061 | C55: Internet fibra | D55: Contas da casa | E55: Débito automático | F55: 119.9 | G55: =IF($D55="","",IF(COUNTIF('Config'!$E$8:$E$15,$D55)>0,"Entrada",IF(COUNTIF('Config'!$G$8:$G$23,$D55)>0,"Saída","Verificar"))) -> Saída
B56: 46061 | C56: Restaurante / bar | D56: Lazer | E56: Cartão de crédito | F56: 86.79 | G56: =IF($D56="","",IF(COUNTIF('Config'!$E$8:$E$15,$D56)>0,"Entrada",IF(COUNTIF('Config'!$G$8:$G$23,$D56)>0,"Saída","Verificar"))) -> Saída
B57: 46062 | C57: Delivery | D57: Alimentação | E57: Cartão de débito | F57: 66.74 | G57: =IF($D57="","",IF(COUNTIF('Config'!$E$8:$E$15,$D57)>0,"Entrada",IF(COUNTIF('Config'!$G$8:$G$23,$D57)>0,"Saída","Verificar"))) -> Saída
B58: 46063 | C58: Aluguel | D58: Moradia | E58: Boleto | F58: 950 | G58: =IF($D58="","",IF(COUNTIF('Config'!$E$8:$E$15,$D58)>0,"Entrada",IF(COUNTIF('Config'!$G$8:$G$23,$D58)>0,"Saída","Verificar"))) -> Saída
B59: 46063 | C59: Condomínio | D59: Moradia | E59: Boleto | F59: 150 | G59: =IF($D59="","",IF(COUNTIF('Config'!$E$8:$E$15,$D59)>0,"Entrada",IF(COUNTIF('Config'!$G$8:$G$23,$D59)>0,"Saída","Verificar"))) -> Saída
B60: 46063 | C60: Plano de saúde | D60: Saúde | E60: Débito automático | F60: 180 | G60: =IF($D60="","",IF(COUNTIF('Config'!$E$8:$E$15,$D60)>0,"Entrada",IF(COUNTIF('Config'!$G$8:$G$23,$D60)>0,"Saída","Verificar"))) -> Saída
...

Sheet Orçamento Pessoal
B1: 🏠 Início | C1: 📊 Painel Geral | E1: 👤 Painel Pessoal | G1: 💼 Painel Negócio | H1: ⚙ Config
B2: PESSOAL | C2: 📝 Lançamentos | E2: 💳 Orçamento | G2: 📅 Resumo anual | H2: 🎯 Metas
B3: NEGÓCIO | C3: 📝 Lançamentos | D3: 🤝 Clientes | E3: 💰 Recebimentos | G3: 🧾 Impostos | H3: 📈 Fluxo de Caixa
B5: 💳 Orçamento mensal — planejado × realizado
B6: Defina quanto pretende gastar em cada categoria. O 'realizado' vem dos lançamentos do mês escolhido.
B7: 📅 Mês de análise: | C7: Setembro | D7: ← escolha o mês no menu suspenso. Os valores planejados (amarelo) valem para todos os meses.
B9: Categoria | C9: Planejado (mês) | D9: Realizado | E9: Diferença | F9: % usado | G9: Progresso | H9: Situação
B10: Renda do mês (entradas) | C10: 4500 | D10: =INDEX('Resumo Pessoal'!$C$18:$N$18,'Dados'!$C$9) -> 4552.89 | E10: =D10-C10 -> 52.89 | F10: =IF(C10>0,D10/C10,"") -> 1.0117533 | G10: =IF(F10="","",REPT("█",MIN(22,ROUND(F10*20,0)))) -> ████████████████████ | H10: =IF(C10=0,"—",IF(D10>=C10,"✓ Meta batida",IF(D10>=C10*0.8,"⚠ Quase lá","✖ Abaixo"))) -> ✓ Meta batida
B11: DESPESAS POR CATEGORIA
B12: =IF('Config'!$G$8="","",'Config'!$G$8) -> Moradia | C12: 1100 | D12: =IF(B12="",0,INDEX('Resumo Pessoal'!$C$20:$N$20,'Dados'!$C$9)) -> 1100 | E12: =C12-D12 -> 0 | F12: =IF(C12>0,D12/C12,"") -> 1 | G12: =IF(F12="","",REPT("█",MIN(22,ROUND(F12*20,0)))) -> ████████████████████ | H12: =IF(C12=0,IF(D12>0,"Sem orçamento","—"),IF(D12>C12,"✖ Estourou",IF(D12>=C12*0.8,"⚠ Atenção","✓ OK"))) -> ⚠ Atenção
B13: =IF('Config'!$G$9="","",'Config'!$G$9) -> Contas da casa | C13: 360 | D13: =IF(B13="",0,INDEX('Resumo Pessoal'!$C$21:$N$21,'Dados'!$C$9)) -> 289.91 | E13: =C13-D13 -> 70.09 | F13: =IF(C13>0,D13/C13,"") -> 0.80530556 | G13: =IF(F13="","",REPT("█",MIN(22,ROUND(F13*20,0)))) -> ████████████████ | H13: =IF(C13=0,IF(D13>0,"Sem orçamento","—"),IF(D13>C13,"✖ Estourou",IF(D13>=C13*0.8,"⚠ Atenção","✓ OK"))) -> ⚠ Atenção
B14: =IF('Config'!$G$10="","",'Config'!$G$10) -> Alimentação | C14: 650 | D14: =IF(B14="",0,INDEX('Resumo Pessoal'!$C$22:$N$22,'Dados'!$C$9)) -> 627.27 | E14: =C14-D14 -> 22.73 | F14: =IF(C14>0,D14/C14,"") -> 0.96503077 | G14: =IF(F14="","",REPT("█",MIN(22,ROUND(F14*20,0)))) -> ███████████████████ | H14: =IF(C14=0,IF(D14>0,"Sem orçamento","—"),IF(D14>C14,"✖ Estourou",IF(D14>=C14*0.8,"⚠ Atenção","✓ OK"))) -> ⚠ Atenção
B15: =IF('Config'!$G$11="","",'Config'!$G$11) -> Transporte | C15: 420 | D15: =IF(B15="",0,INDEX('Resumo Pessoal'!$C$23:$N$23,'Dados'!$C$9)) -> 264.51 | E15: =C15-D15 -> 155.49 | F15: =IF(C15>0,D15/C15,"") -> 0.62978571 | G15: =IF(F15="","",REPT("█",MIN(22,ROUND(F15*20,0)))) -> █████████████ | H15: =IF(C15=0,IF(D15>0,"Sem orçamento","—"),IF(D15>C15,"✖ Estourou",IF(D15>=C15*0.8,"⚠ Atenção","✓ OK"))) -> ✓ OK
B16: =IF('Config'!$G$12="","",'Config'!$G$12) -> Saúde | C16: 250 | D16: =IF(B16="",0,INDEX('Resumo Pessoal'!$C$24:$N$24,'Dados'!$C$9)) -> 255.85 | E16: =C16-D16 -> -5.85 | F16: =IF(C16>0,D16/C16,"") -> 1.0234 | G16: =IF(F16="","",REPT("█",MIN(22,ROUND(F16*20,0)))) -> ████████████████████ | H16: =IF(C16=0,IF(D16>0,"Sem orçamento","—"),IF(D16>C16,"✖ Estourou",IF(D16>=C16*0.8,"⚠ Atenção","✓ OK"))) -> ✖ Estourou
B17: =IF('Config'!$G$13="","",'Config'!$G$13) -> Educação | C17: 150 | D17: =IF(B17="",0,INDEX('Resumo Pessoal'!$C$25:$N$25,'Dados'!$C$9)) -> 149 | E17: =C17-D17 -> 1 | F17: =IF(C17>0,D17/C17,"") -> 0.99333333 | G17: =IF(F17="","",REPT("█",MIN(22,ROUND(F17*20,0)))) -> ████████████████████ | H17: =IF(C17=0,IF(D17>0,"Sem orçamento","—"),IF(D17>C17,"✖ Estourou",IF(D17>=C17*0.8,"⚠ Atenção","✓ OK"))) -> ⚠ Atenção
B18: =IF('Config'!$G$14="","",'Config'!$G$14) -> Lazer | C18: 250 | D18: =IF(B18="",0,INDEX('Resumo Pessoal'!$C$26:$N$26,'Dados'!$C$9)) -> 201.67 | E18: =C18-D18 -> 48.33 | F18: =IF(C18>0,D18/C18,"") -> 0.80668 | G18: =IF(F18="","",REPT("█",MIN(22,ROUND(F18*20,0)))) -> ████████████████ | H18: =IF(C18=0,IF(D18>0,"Sem orçamento","—"),IF(D18>C18,"✖ Estourou",IF(D18>=C18*0.8,"⚠ Atenção","✓ OK"))) -> ⚠ Atenção
B19: =IF('Config'!$G$15="","",'Config'!$G$15) -> Vestuário | C19: 100 | D19: =IF(B19="",0,INDEX('Resumo Pessoal'!$C$27:$N$27,'Dados'!$C$9)) -> 138.36 | E19: =C19-D19 -> -38.36 | F19: =IF(C19>0,D19/C19,"") -> 1.3836 | G19: =IF(F19="","",REPT("█",MIN(22,ROUND(F19*20,0)))) -> ██████████████████████ | H19: =IF(C19=0,IF(D19>0,"Sem orçamento","—"),IF(D19>C19,"✖ Estourou",IF(D19>=C19*0.8,"⚠ Atenção","✓ OK"))) -> ✖ Estourou
B20: =IF('Config'!$G$16="","",'Config'!$G$16) -> Assinaturas | C20: 90 | D20: =IF(B20="",0,INDEX('Resumo Pessoal'!$C$28:$N$28,'Dados'!$C$9)) -> 87.7 | E20: =C20-D20 -> 2.3 | F20: =IF(C20>0,D20/C20,"") -> 0.97444444 | G20: =IF(F20="","",REPT("█",MIN(22,ROUND(F20*20,0)))) -> ███████████████████ | H20: =IF(C20=0,IF(D20>0,"Sem orçamento","—"),IF(D20>C20,"✖ Estourou",IF(D20>=C20*0.8,"⚠ Atenção","✓ OK"))) -> ⚠ Atenção
B21: =IF('Config'!$G$17="","",'Config'!$G$17) -> Cuidados pessoais | C21: 200 | D21: =IF(B21="",0,INDEX('Resumo Pessoal'!$C$29:$N$29,'Dados'!$C$9)) -> 175.11 | E21: =C21-D21 -> 24.89 | F21: =IF(C21>0,D21/C21,"") -> 0.87555 | G21: =IF(F21="","",REPT("█",MIN(22,ROUND(F21*20,0)))) -> ██████████████████ | H21: =IF(C21=0,IF(D21>0,"Sem orçamento","—"),IF(D21>C21,"✖ Estourou",IF(D21>=C21*0.8,"⚠ Atenção","✓ OK"))) -> ⚠ Atenção
B22: =IF('Config'!$G$18="","",'Config'!$G$18) -> Pets | C22: 0 | D22: =IF(B22="",0,INDEX('Resumo Pessoal'!$C$30:$N$30,'Dados'!$C$9)) -> 0 | E22: =C22-D22 -> 0 | F22: =IF(C22>0,D22/C22,"") | G22: =IF(F22="","",REPT("█",MIN(22,ROUND(F22*20,0)))) | H22: =IF(C22=0,IF(D22>0,"Sem orçamento","—"),IF(D22>C22,"✖ Estourou",IF(D22>=C22*0.8,"⚠ Atenção","✓ OK"))) -> —
B23: =IF('Config'!$G$19="","",'Config'!$G$19) -> Presentes e doações | C23: 80 | D23: =IF(B23="",0,INDEX('Resumo Pessoal'!$C$31:$N$31,'Dados'!$C$9)) -> 50 | E23: =C23-D23 -> 30 | F23: =IF(C23>0,D23/C23,"") -> 0.625 | G23: =IF(F23="","",REPT("█",MIN(22,ROUND(F23*20,0)))) -> █████████████ | H23: =IF(C23=0,IF(D23>0,"Sem orçamento","—"),IF(D23>C23,"✖ Estourou",IF(D23>=C23*0.8,"⚠ Atenção","✓ OK"))) -> ✓ OK
B24: =IF('Config'!$G$20="","",'Config'!$G$20) -> Dívidas e financiamentos | C24: 0 | D24: =IF(B24="",0,INDEX('Resumo Pessoal'!$C$32:$N$32,'Dados'!$C$9)) -> 0 | E24: =C24-D24 -> 0 | F24: =IF(C24>0,D24/C24,"") | G24: =IF(F24="","",REPT("█",MIN(22,ROUND(F24*20,0)))) | H24: =IF(C24=0,IF(D24>0,"Sem orçamento","—"),IF(D24>C24,"✖ Estourou",IF(D24>=C24*0.8,"⚠ Atenção","✓ OK"))) -> —
B25: =IF('Config'!$G$21="","",'Config'!$G$21) -> Reserva e Metas | C25: 600 | D25: =IF(B25="",0,INDEX('Resumo Pessoal'!$C$33:$N$33,'Dados'!$C$9)) -> 600 | E25: =D25-C25 -> 0 | F25: =IF(C25>0,D25/C25,"") -> 1 | G25: =IF(F25="","",REPT("█",MIN(22,ROUND(F25*20,0)))) -> ████████████████████ | H25: =IF(C25=0,"—",IF(D25>=C25,"✓ Meta batida",IF(D25>=C25*0.8,"⚠ Quase lá","✖ Abaixo"))) -> ✓ Meta batida
B26: =IF('Config'!$G$22="","",'Config'!$G$22) -> Impostos pessoais | C26: 80 | D26: =IF(B26="",0,INDEX('Resumo Pessoal'!$C$34:$N$34,'Dados'!$C$9)) -> 0 | E26: =C26-D26 -> 80 | F26: =IF(C26>0,D26/C26,"") -> 0 | G26: =IF(F26="","",REPT("█",MIN(22,ROUND(F26*20,0)))) | H26: =IF(C26=0,IF(D26>0,"Sem orçamento","—"),IF(D26>C26,"✖ Estourou",IF(D26>=C26*0.8,"⚠ Atenção","✓ OK"))) -> ✓ OK
B27: =IF('Config'!$G$23="","",'Config'!$G$23) -> Outros | C27: 80 | D27: =IF(B27="",0,INDEX('Resumo Pessoal'!$C$35:$N$35,'Dados'!$C$9)) -> 53.46 | E27: =C27-D27 -> 26.54 | F27: =IF(C27>0,D27/C27,"") -> 0.66825 | G27: =IF(F27="","",REPT("█",MIN(22,ROUND(F27*20,0)))) -> █████████████ | H27: =IF(C27=0,IF(D27>0,"Sem orçamento","—"),IF(D27>C27,"✖ Estourou",IF(D27>=C27*0.8,"⚠ Atenção","✓ OK"))) -> ✓ OK
B28: TOTAL DAS DESPESAS | C28: =SUM(C12:C27) -> 4410 | D28: =SUM(D12:D27) -> 3992.84 | E28: =C28-D28 -> 417.16 | F28: =IF(C28>0,D28/C28,"") -> 0.9054059 | G28: =IF(F28="","",REPT("█",MIN(22,ROUND(F28*20,0)))) -> ██████████████████ | H28: =IF(C28=0,"—",IF(D28>C28,"✖ Estourou",IF(D28>=C28*0.8,"⚠ Atenção","✓ OK"))) -> ⚠ Atenção
B29: SALDO (renda − despesas) | C29: =C10-C28 -> 90 | D29: =D10-D28 -> 560.05 | E29: =D29-C29 -> 470.05

Sheet Resumo Pessoal
B1: 🏠 Início | D1: 📊 Painel Geral | G1: 👤 Painel Pessoal | K1: 💼 Painel Negócio | O1: ⚙ Config
B2: PESSOAL | D2: 📝 Lançamentos | G2: 💳 Orçamento | K2: 📅 Resumo anual | O2: 🎯 Metas
B3: NEGÓCIO | C3: 📝 Lançamentos | F3: 🤝 Clientes | I3: 💰 Recebimentos | L3: 🧾 Impostos | O3: 📈 Fluxo de Caixa
B5: 📅 Resumo anual — entradas e saídas por mês
B6: Totalizado automaticamente a partir da aba de lançamentos. Cores destacam saldos positivos e negativos.
C7: =DATE('Config'!$C$8,1,1) -> 46023 | D7: =DATE('Config'!$C$8,2,1) -> 46054 | E7: =DATE('Config'!$C$8,3,1) -> 46082 | F7: =DATE('Config'!$C$8,4,1) -> 46113 | G7: =DATE('Config'!$C$8,5,1) -> 46143 | H7: =DATE('Config'!$C$8,6,1) -> 46174 | I7: =DATE('Config'!$C$8,7,1) -> 46204 | J7: =DATE('Config'!$C$8,8,1) -> 46235 | K7: =DATE('Config'!$C$8,9,1) -> 46266 | L7: =DATE('Config'!$C$8,10,1) -> 46296 | M7: =DATE('Config'!$C$8,11,1) -> 46327 | N7: =DATE('Config'!$C$8,12,1) -> 46357
B8: Categoria | C8: =INDEX('Config'!$L$8:$L$19,1) -> Jan | D8: =INDEX('Config'!$L$8:$L$19,2) -> Fev | E8: =INDEX('Config'!$L$8:$L$19,3) -> Mar | F8: =INDEX('Config'!$L$8:$L$19,4) -> Abr | G8: =INDEX('Config'!$L$8:$L$19,5) -> Mai | H8: =INDEX('Config'!$L$8:$L$19,6) -> Jun | I8: =INDEX('Config'!$L$8:$L$19,7) -> Jul | J8: =INDEX('Config'!$L$8:$L$19,8) -> Ago | K8: =INDEX('Config'!$L$8:$L$19,9) -> Set | L8: =INDEX('Config'!$L$8:$L$19,10) -> Out | M8: =INDEX('Config'!$L$8:$L$19,11) -> Nov | N8: =INDEX('Config'!$L$8:$L$19,12) -> Dez | O8: Total | P8: Média/mês | Q8: % das saídas
B9: ▲ ENTRADAS
B10: =IF('Config'!$E$8="","",'Config'!$E$8) -> Pró-labore / Retirada do negócio | C10: =IF($B10="",0,SUMIFS('Lanç. Pessoal'!$F$11:$F$1510,'Lanç. Pessoal'!$D$11:$D$1510,$B10,'Lanç. Pessoal'!$B$11:$B$1510,">="&C$7,'Lanç. Pessoal'!$B$11:$B$1510,"<"&EDATE(C$7,1))) -> 4500 | D10: =IF($B10="",0,SUMIFS('Lanç. Pessoal'!$F$11:$F$1510,'Lanç. Pessoal'!$D$11:$D$1510,$B10,'Lanç. Pessoal'!$B$11:$B$1510,">="&D$7,'Lanç. Pessoal'!$B$11:$B$1510,"<"&EDATE(D$7,1))) -> 4500 | E10: =IF($B10="",0,SUMIFS('Lanç. Pessoal'!$F$11:$F$1510,'Lanç. Pessoal'!$D$11:$D$1510,$B10,'Lanç. Pessoal'!$B$11:$B$1510,">="&E$7,'Lanç. Pessoal'!$B$11:$B$1510,"<"&EDATE(E$7,1))) -> 4500 | F10: =IF($B10="",0,SUMIFS('Lanç. Pessoal'!$F$11:$F$1510,'Lanç. Pessoal'!$D$11:$D$1510,$B10,'Lanç. Pessoal'!$B$11:$B$1510,">="&F$7,'Lanç. Pessoal'!$B$11:$B$1510,"<"&EDATE(F$7,1))) -> 4500 | G10: =IF($B10="",0,SUMIFS('Lanç. Pessoal'!$F$11:$F$1510,'Lanç. Pessoal'!$D$11:$D$1510,$B10,'Lanç. Pessoal'!$B$11:$B$1510,">="&G$7,'Lanç. Pessoal'!$B$11:$B$1510,"<"&EDATE(G$7,1))) -> 4500 | H10: =IF($B10="",0,SUMIFS('Lanç. Pessoal'!$F$11:$F$1510,'Lanç. Pessoal'!$D$11:$D$1510,$B10,'Lanç. Pessoal'!$B$11:$B$1510,">="&H$7,'Lanç. Pessoal'!$B$11:$B$1510,"<"&EDATE(H$7,1))) -> 4500 | I10: =IF($B10="",0,SUMIFS('Lanç. Pessoal'!$F$11:$F$1510,'Lanç. Pessoal'!$D$11:$D$1510,$B10,'Lanç. Pessoal'!$B$11:$B$1510,">="&I$7,'Lanç. Pessoal'!$B$11:$B$1510,"<"&EDATE(I$7,1))) -> 4500 | J10: =IF($B10="",0,SUMIFS('Lanç. Pessoal'!$F$11:$F$1510,'Lanç. Pessoal'!$D$11:$D$1510,$B10,'Lanç. Pessoal'!$B$11:$B$1510,">="&J$7,'Lanç. Pessoal'!$B$11:$B$1510,"<"&EDATE(J$7,1))) -> 4500 | ... N10: =IF($B10="",0,SUMIFS('Lanç. Pessoal'!$F$11:$F$1510,'Lanç. Pessoal'!$D$11:$D$1510,$B10,'Lanç. Pessoal'!$B$11:$B$1510,">="&N$7,'Lanç. Pessoal'!$B$11:$B$1510,"<"&EDATE(N$7,1))) -> 0 | O10: =SUM(C10:N10) -> 40500 | P10: =IFERROR(O10/'Dados'!$C$11,0) -> 4500
B11: =IF('Config'!$E$9="","",'Config'!$E$9) -> Salário / Renda fixa | C11: =IF($B11="",0,SUMIFS('Lanç. Pessoal'!$F$11:$F$1510,'Lanç. Pessoal'!$D$11:$D$1510,$B11,'Lanç. Pessoal'!$B$11:$B$1510,">="&C$7,'Lanç. Pessoal'!$B$11:$B$1510,"<"&EDATE(C$7,1))) -> 0 | D11: =IF($B11="",0,SUMIFS('Lanç. Pessoal'!$F$11:$F$1510,'Lanç. Pessoal'!$D$11:$D$1510,$B11,'Lanç. Pessoal'!$B$11:$B$1510,">="&D$7,'Lanç. Pessoal'!$B$11:$B$1510,"<"&EDATE(D$7,1))) -> 0 | E11: =IF($B11="",0,SUMIFS('Lanç. Pessoal'!$F$11:$F$1510,'Lanç. Pessoal'!$D$11:$D$1510,$B11,'Lanç. Pessoal'!$B$11:$B$1510,">="&E$7,'Lanç. Pessoal'!$B$11:$B$1510,"<"&EDATE(E$7,1))) -> 0 | F11: =IF($B11="",0,SUMIFS('Lanç. Pessoal'!$F$11:$F$1510,'Lanç. Pessoal'!$D$11:$D$1510,$B11,'Lanç. Pessoal'!$B$11:$B$1510,">="&F$7,'Lanç. Pessoal'!$B$11:$B$1510,"<"&EDATE(F$7,1))) -> 0 | G11: =IF($B11="",0,SUMIFS('Lanç. Pessoal'!$F$11:$F$1510,'Lanç. Pessoal'!$D$11:$D$1510,$B11,'Lanç. Pessoal'!$B$11:$B$1510,">="&G$7,'Lanç. Pessoal'!$B$11:$B$1510,"<"&EDATE(G$7,1))) -> 0 | H11: =IF($B11="",0,SUMIFS('Lanç. Pessoal'!$F$11:$F$1510,'Lanç. Pessoal'!$D$11:$D$1510,$B11,'Lanç. Pessoal'!$B$11:$B$1510,">="&H$7,'Lanç. Pessoal'!$B$11:$B$1510,"<"&EDATE(H$7,1))) -> 0 | I11: =IF($B11="",0,SUMIFS('Lanç. Pessoal'!$F$11:$F$1510,'Lanç. Pessoal'!$D$11:$D$1510,$B11,'Lanç. Pessoal'!$B$11:$B$1510,">="&I$7,'Lanç. Pessoal'!$B$11:$B$1510,"<"&EDATE(I$7,1))) -> 0 | J11: =IF($B11="",0,SUMIFS('Lanç. Pessoal'!$F$11:$F$1510,'Lanç. Pessoal'!$D$11:$D$1510,$B11,'Lanç. Pessoal'!$B$11:$B$1510,">="&J$7,'Lanç. Pessoal'!$B$11:$B$1510,"<"&EDATE(J$7,1))) -> 0 | ... N11: =IF($B11="",0,SUMIFS('Lanç. Pessoal'!$F$11:$F$1510,'Lanç. Pessoal'!$D$11:$D$1510,$B11,'Lanç. Pessoal'!$B$11:$B$1510,">="&N$7,'Lanç. Pessoal'!$B$11:$B$1510,"<"&EDATE(N$7,1))) -> 0 | O11: =SUM(C11:N11) -> 0 | P11: =IFERROR(O11/'Dados'!$C$11,0) -> 0
B12: =IF('Config'!$E$10="","",'Config'!$E$10) -> Renda extra | C12: =IF($B12="",0,SUMIFS('Lanç. Pessoal'!$F$11:$F$1510,'Lanç. Pessoal'!$D$11:$D$1510,$B12,'Lanç. Pessoal'!$B$11:$B$1510,">="&C$7,'Lanç. Pessoal'!$B$11:$B$1510,"<"&EDATE(C$7,1))) -> 0 | D12: =IF($B12="",0,SUMIFS('Lanç. Pessoal'!$F$11:$F$1510,'Lanç. Pessoal'!$D$11:$D$1510,$B12,'Lanç. Pessoal'!$B$11:$B$1510,">="&D$7,'Lanç. Pessoal'!$B$11:$B$1510,"<"&EDATE(D$7,1))) -> 0 | E12: =IF($B12="",0,SUMIFS('Lanç. Pessoal'!$F$11:$F$1510,'Lanç. Pessoal'!$D$11:$D$1510,$B12,'Lanç. Pessoal'!$B$11:$B$1510,">="&E$7,'Lanç. Pessoal'!$B$11:$B$1510,"<"&EDATE(E$7,1))) -> 0 | F12: =IF($B12="",0,SUMIFS('Lanç. Pessoal'!$F$11:$F$1510,'Lanç. Pessoal'!$D$11:$D$1510,$B12,'Lanç. Pessoal'!$B$11:$B$1510,">="&F$7,'Lanç. Pessoal'!$B$11:$B$1510,"<"&EDATE(F$7,1))) -> 0 | G12: =IF($B12="",0,SUMIFS('Lanç. Pessoal'!$F$11:$F$1510,'Lanç. Pessoal'!$D$11:$D$1510,$B12,'Lanç. Pessoal'!$B$11:$B$1510,">="&G$7,'Lanç. Pessoal'!$B$11:$B$1510,"<"&EDATE(G$7,1))) -> 0 | H12: =IF($B12="",0,SUMIFS('Lanç. Pessoal'!$F$11:$F$1510,'Lanç. Pessoal'!$D$11:$D$1510,$B12,'Lanç. Pessoal'!$B$11:$B$1510,">="&H$7,'Lanç. Pessoal'!$B$11:$B$1510,"<"&EDATE(H$7,1))) -> 0 | I12: =IF($B12="",0,SUMIFS('Lanç. Pessoal'!$F$11:$F$1510,'Lanç. Pessoal'!$D$11:$D$1510,$B12,'Lanç. Pessoal'!$B$11:$B$1510,">="&I$7,'Lanç. Pessoal'!$B$11:$B$1510,"<"&EDATE(I$7,1))) -> 0 | J12: =IF($B12="",0,SUMIFS('Lanç. Pessoal'!$F$11:$F$1510,'Lanç. Pessoal'!$D$11:$D$1510,$B12,'Lanç. Pessoal'!$B$11:$B$1510,">="&J$7,'Lanç. Pessoal'!$B$11:$B$1510,"<"&EDATE(J$7,1))) -> 0 | ... N12: =IF($B12="",0,SUMIFS('Lanç. Pessoal'!$F$11:$F$1510,'Lanç. Pessoal'!$D$11:$D$1510,$B12,'Lanç. Pessoal'!$B$11:$B$1510,">="&N$7,'Lanç. Pessoal'!$B$11:$B$1510,"<"&EDATE(N$7,1))) -> 0 | O12: =SUM(C12:N12) -> 0 | P12: =IFERROR(O12/'Dados'!$C$11,0) -> 0
B13: =IF('Config'!$E$11="","",'Config'!$E$11) -> Rendimentos de investimentos | C13: =IF($B13="",0,SUMIFS('Lanç. Pessoal'!$F$11:$F$1510,'Lanç. Pessoal'!$D$11:$D$1510,$B13,'Lanç. Pessoal'!$B$11:$B$1510,">="&C$7,'Lanç. Pessoal'!$B$11:$B$1510,"<"&EDATE(C$7,1))) -> 46.63 | D13: =IF($B13="",0,SUMIFS('Lanç. Pessoal'!$F$11:$F$1510,'Lanç. Pessoal'!$D$11:$D$1510,$B13,'Lanç. Pessoal'!$B$11:$B$1510,">="&D$7,'Lanç. Pessoal'!$B$11:$B$1510,"<"&EDATE(D$7,1))) -> 50.78 | E13: =IF($B13="",0,SUMIFS('Lanç. Pessoal'!$F$11:$F$1510,'Lanç. Pessoal'!$D$11:$D$1510,$B13,'Lanç. Pessoal'!$B$11:$B$1510,">="&E$7,'Lanç. Pessoal'!$B$11:$B$1510,"<"&EDATE(E$7,1))) -> 58.6 | F13: =IF($B13="",0,SUMIFS('Lanç. Pessoal'!$F$11:$F$1510,'Lanç. Pessoal'!$D$11:$D$1510,$B13,'Lanç. Pessoal'!$B$11:$B$1510,">="&F$7,'Lanç. Pessoal'!$B$11:$B$1510,"<"&EDATE(F$7,1))) -> 69.41 | G13: =IF($B13="",0,SUMIFS('Lanç. Pessoal'!$F$11:$F$1510,'Lanç. Pessoal'!$D$11:$D$1510,$B13,'Lanç. Pessoal'!$B$11:$B$1510,">="&G$7,'Lanç. Pessoal'!$B$11:$B$1510,"<"&EDATE(G$7,1))) -> 53.22 | H13: =IF($B13="",0,SUMIFS('Lanç. Pessoal'!$F$11:$F$1510,'Lanç. Pessoal'!$D$11:$D$1510,$B13,'Lanç. Pessoal'!$B$11:$B$1510,">="&H$7,'Lanç. Pessoal'!$B$11:$B$1510,"<"&EDATE(H$7,1))) -> 41.87 | I13: =IF($B13="",0,SUMIFS('Lanç. Pessoal'!$F$11:$F$1510,'Lanç. Pessoal'!$D$11:$D$1510,$B13,'Lanç. Pessoal'!$B$11:$B$1510,">="&I$7,'Lanç. Pessoal'!$B$11:$B$1510,"<"&EDATE(I$7,1))) -> 60.59 | J13: =IF($B13="",0,SUMIFS('Lanç. Pessoal'!$F$11:$F$1510,'Lanç. Pessoal'!$D$11:$D$1510,$B13,'Lanç. Pessoal'!$B$11:$B$1510,">="&J$7,'Lanç. Pessoal'!$B$11:$B$1510,"<"&EDATE(J$7,1))) -> 44.92 | ... N13: =IF($B13="",0,SUMIFS('Lanç. Pessoal'!$F$11:$F$1510,'Lanç. Pessoal'!$D$11:$D$1510,$B13,'Lanç. Pessoal'!$B$11:$B$1510,">="&N$7,'Lanç. Pessoal'!$B$11:$B$1510,"<"&EDATE(N$7,1))) -> 0 | O13: =SUM(C13:N13) -> 478.91 | P13: =IFERROR(O13/'Dados'!$C$11,0) -> 53.212222
B14: =IF('Config'!$E$12="","",'Config'!$E$12) -> Reembolsos | C14: =IF($B14="",0,SUMIFS('Lanç. Pessoal'!$F$11:$F$1510,'Lanç. Pessoal'!$D$11:$D$1510,$B14,'Lanç. Pessoal'!$B$11:$B$1510,">="&C$7,'Lanç. Pessoal'!$B$11:$B$1510,"<"&EDATE(C$7,1))) -> 0 | D14: =IF($B14="",0,SUMIFS('Lanç. Pessoal'!$F$11:$F$1510,'Lanç. Pessoal'!$D$11:$D$1510,$B14,'Lanç. Pessoal'!$B$11:$B$1510,">="&D$7,'Lanç. Pessoal'!$B$11:$B$1510,"<"&EDATE(D$7,1))) -> 0 | E14: =IF($B14="",0,SUMIFS('Lanç. Pessoal'!$F$11:$F$1510,'Lanç. Pessoal'!$D$11:$D$1510,$B14,'Lanç. Pessoal'!$B$11:$B$1510,">="&E$7,'Lanç. Pessoal'!$B$11:$B$1510,"<"&EDATE(E$7,1))) -> 386.08 | F14: =IF($B14="",0,SUMIFS('Lanç. Pessoal'!$F$11:$F$1510,'Lanç. Pessoal'!$D$11:$D$1510,$B14,'Lanç. Pessoal'!$B$11:$B$1510,">="&F$7,'Lanç. Pessoal'!$B$11:$B$1510,"<"&EDATE(F$7,1))) -> 0 | G14: =IF($B14="",0,SUMIFS('Lanç. Pessoal'!$F$11:$F$1510,'Lanç. Pessoal'!$D$11:$D$1510,$B14,'Lanç. Pessoal'!$B$11:$B$1510,">="&G$7,'Lanç. Pessoal'!$B$11:$B$1510,"<"&EDATE(G$7,1))) -> 0 | H14: =IF($B14="",0,SUMIFS('Lanç. Pessoal'!$F$11:$F$1510,'Lanç. Pessoal'!$D$11:$D$1510,$B14,'Lanç. Pessoal'!$B$11:$B$1510,">="&H$7,'Lanç. Pessoal'!$B$11:$B$1510,"<"&EDATE(H$7,1))) -> 360.13 | I14: =IF($B14="",0,SUMIFS('Lanç. Pessoal'!$F$11:$F$1510,'Lanç. Pessoal'!$D$11:$D$1510,$B14,'Lanç. Pessoal'!$B$11:$B$1510,">="&I$7,'Lanç. Pessoal'!$B$11:$B$1510,"<"&EDATE(I$7,1))) -> 0 | J14: =IF($B14="",0,SUMIFS('Lanç. Pessoal'!$F$11:$F$1510,'Lanç. Pessoal'!$D$11:$D$1510,$B14,'Lanç. Pessoal'!$B$11:$B$1510,">="&J$7,'Lanç. Pessoal'!$B$11:$B$1510,"<"&EDATE(J$7,1))) -> 0 | ... N14: =IF($B14="",0,SUMIFS('Lanç. Pessoal'!$F$11:$F$1510,'Lanç. Pessoal'!$D$11:$D$1510,$B14,'Lanç. Pessoal'!$B$11:$B$1510,">="&N$7,'Lanç. Pessoal'!$B$11:$B$1510,"<"&EDATE(N$7,1))) -> 0 | O14: =SUM(C14:N14) -> 746.21 | P14: =IFERROR(O14/'Dados'!$C$11,0) -> 82.912222
B15: =IF('Config'!$E$13="","",'Config'!$E$13) -> Aluguéis recebidos | C15: =IF($B15="",0,SUMIFS('Lanç. Pessoal'!$F$11:$F$1510,'Lanç. Pessoal'!$D$11:$D$1510,$B15,'Lanç. Pessoal'!$B$11:$B$1510,">="&C$7,'Lanç. Pessoal'!$B$11:$B$1510,"<"&EDATE(C$7,1))) -> 0 | D15: =IF($B15="",0,SUMIFS('Lanç. Pessoal'!$F$11:$F$1510,'Lanç. Pessoal'!$D$11:$D$1510,$B15,'Lanç. Pessoal'!$B$11:$B$1510,">="&D$7,'Lanç. Pessoal'!$B$11:$B$1510,"<"&EDATE(D$7,1))) -> 0 | E15: =IF($B15="",0,SUMIFS('Lanç. Pessoal'!$F$11:$F$1510,'Lanç. Pessoal'!$D$11:$D$1510,$B15,'Lanç. Pessoal'!$B$11:$B$1510,">="&E$7,'Lanç. Pessoal'!$B$11:$B$1510,"<"&EDATE(E$7,1))) -> 0 | F15: =IF($B15="",0,SUMIFS('Lanç. Pessoal'!$F$11:$F$1510,'Lanç. Pessoal'!$D$11:$D$1510,$B15,'Lanç. Pessoal'!$B$11:$B$1510,">="&F$7,'Lanç. Pessoal'!$B$11:$B$1510,"<"&EDATE(F$7,1))) -> 0 | G15: =IF($B15="",0,SUMIFS('Lanç. Pessoal'!$F$11:$F$1510,'Lanç. Pessoal'!$D$11:$D$1510,$B15,'Lanç. Pessoal'!$B$11:$B$1510,">="&G$7,'Lanç. Pessoal'!$B$11:$B$1510,"<"&EDATE(G$7,1))) -> 0 | H15: =IF($B15="",0,SUMIFS('Lanç. Pessoal'!$F$11:$F$1510,'Lanç. Pessoal'!$D$11:$D$1510,$B15,'Lanç. Pessoal'!$B$11:$B$1510,">="&H$7,'Lanç. Pessoal'!$B$11:$B$1510,"<"&EDATE(H$7,1))) -> 0 | I15: =IF($B15="",0,SUMIFS('Lanç. Pessoal'!$F$11:$F$1510,'Lanç. Pessoal'!$D$11:$D$1510,$B15,'Lanç. Pessoal'!$B$11:$B$1510,">="&I$7,'Lanç. Pessoal'!$B$11:$B$1510,"<"&EDATE(I$7,1))) -> 0 | J15: =IF($B15="",0,SUMIFS('Lanç. Pessoal'!$F$11:$F$1510,'Lanç. Pessoal'!$D$11:$D$1510,$B15,'Lanç. Pessoal'!$B$11:$B$1510,">="&J$7,'Lanç. Pessoal'!$B$11:$B$1510,"<"&EDATE(J$7,1))) -> 0 | ... N15: =IF($B15="",0,SUMIFS('Lanç. Pessoal'!$F$11:$F$1510,'Lanç. Pessoal'!$D$11:$D$1510,$B15,'Lanç. Pessoal'!$B$11:$B$1510,">="&N$7,'Lanç. Pessoal'!$B$11:$B$1510,"<"&EDATE(N$7,1))) -> 0 | O15: =SUM(C15:N15) -> 0 | P15: =IFERROR(O15/'Dados'!$C$11,0) -> 0
B16: =IF('Config'!$E$14="","",'Config'!$E$14) -> Presentes recebidos | C16: =IF($B16="",0,SUMIFS('Lanç. Pessoal'!$F$11:$F$1510,'Lanç. Pessoal'!$D$11:$D$1510,$B16,'Lanç. Pessoal'!$B$11:$B$1510,">="&C$7,'Lanç. Pessoal'!$B$11:$B$1510,"<"&EDATE(C$7,1))) -> 0 | D16: =IF($B16="",0,SUMIFS('Lanç. Pessoal'!$F$11:$F$1510,'Lanç. Pessoal'!$D$11:$D$1510,$B16,'Lanç. Pessoal'!$B$11:$B$1510,">="&D$7,'Lanç. Pessoal'!$B$11:$B$1510,"<"&EDATE(D$7,1))) -> 0 | E16: =IF($B16="",0,SUMIFS('Lanç. Pessoal'!$F$11:$F$1510,'Lanç. Pessoal'!$D$11:$D$1510,$B16,'Lanç. Pessoal'!$B$11:$B$1510,">="&E$7,'Lanç. Pessoal'!$B$11:$B$1510,"<"&EDATE(E$7,1))) -> 0 | F16: =IF($B16="",0,SUMIFS('Lanç. Pessoal'!$F$11:$F$1510,'Lanç. Pessoal'!$D$11:$D$1510,$B16,'Lanç. Pessoal'!$B$11:$B$1510,">="&F$7,'Lanç. Pessoal'!$B$11:$B$1510,"<"&EDATE(F$7,1))) -> 0 | G16: =IF($B16="",0,SUMIFS('Lanç. Pessoal'!$F$11:$F$1510,'Lanç. Pessoal'!$D$11:$D$1510,$B16,'Lanç. Pessoal'!$B$11:$B$1510,">="&G$7,'Lanç. Pessoal'!$B$11:$B$1510,"<"&EDATE(G$7,1))) -> 0 | H16: =IF($B16="",0,SUMIFS('Lanç. Pessoal'!$F$11:$F$1510,'Lanç. Pessoal'!$D$11:$D$1510,$B16,'Lanç. Pessoal'!$B$11:$B$1510,">="&H$7,'Lanç. Pessoal'!$B$11:$B$1510,"<"&EDATE(H$7,1))) -> 0 | I16: =IF($B16="",0,SUMIFS('Lanç. Pessoal'!$F$11:$F$1510,'Lanç. Pessoal'!$D$11:$D$1510,$B16,'Lanç. Pessoal'!$B$11:$B$1510,">="&I$7,'Lanç. Pessoal'!$B$11:$B$1510,"<"&EDATE(I$7,1))) -> 0 | J16: =IF($B16="",0,SUMIFS('Lanç. Pessoal'!$F$11:$F$1510,'Lanç. Pessoal'!$D$11:$D$1510,$B16,'Lanç. Pessoal'!$B$11:$B$1510,">="&J$7,'Lanç. Pessoal'!$B$11:$B$1510,"<"&EDATE(J$7,1))) -> 0 | ... N16: =IF($B16="",0,SUMIFS('Lanç. Pessoal'!$F$11:$F$1510,'Lanç. Pessoal'!$D$11:$D$1510,$B16,'Lanç. Pessoal'!$B$11:$B$1510,">="&N$7,'Lanç. Pessoal'!$B$11:$B$1510,"<"&EDATE(N$7,1))) -> 0 | O16: =SUM(C16:N16) -> 0 | P16: =IFERROR(O16/'Dados'!$C$11,0) -> 0
B17: =IF('Config'!$E$15="","",'Config'!$E$15) -> Outras entradas | C17: =IF($B17="",0,SUMIFS('Lanç. Pessoal'!$F$11:$F$1510,'Lanç. Pessoal'!$D$11:$D$1510,$B17,'Lanç. Pessoal'!$B$11:$B$1510,">="&C$7,'Lanç. Pessoal'!$B$11:$B$1510,"<"&EDATE(C$7,1))) -> 0 | D17: =IF($B17="",0,SUMIFS('Lanç. Pessoal'!$F$11:$F$1510,'Lanç. Pessoal'!$D$11:$D$1510,$B17,'Lanç. Pessoal'!$B$11:$B$1510,">="&D$7,'Lanç. Pessoal'!$B$11:$B$1510,"<"&EDATE(D$7,1))) -> 0 | E17: =IF($B17="",0,SUMIFS('Lanç. Pessoal'!$F$11:$F$1510,'Lanç. Pessoal'!$D$11:$D$1510,$B17,'Lanç. Pessoal'!$B$11:$B$1510,">="&E$7,'Lanç. Pessoal'!$B$11:$B$1510,"<"&EDATE(E$7,1))) -> 0 | F17: =IF($B17="",0,SUMIFS('Lanç. Pessoal'!$F$11:$F$1510,'Lanç. Pessoal'!$D$11:$D$1510,$B17,'Lanç. Pessoal'!$B$11:$B$1510,">="&F$7,'Lanç. Pessoal'!$B$11:$B$1510,"<"&EDATE(F$7,1))) -> 0 | G17: =IF($B17="",0,SUMIFS('Lanç. Pessoal'!$F$11:$F$1510,'Lanç. Pessoal'!$D$11:$D$1510,$B17,'Lanç. Pessoal'!$B$11:$B$1510,">="&G$7,'Lanç. Pessoal'!$B$11:$B$1510,"<"&EDATE(G$7,1))) -> 0 | H17: =IF($B17="",0,SUMIFS('Lanç. Pessoal'!$F$11:$F$1510,'Lanç. Pessoal'!$D$11:$D$1510,$B17,'Lanç. Pessoal'!$B$11:$B$1510,">="&H$7,'Lanç. Pessoal'!$B$11:$B$1510,"<"&EDATE(H$7,1))) -> 0 | I17: =IF($B17="",0,SUMIFS('Lanç. Pessoal'!$F$11:$F$1510,'Lanç. Pessoal'!$D$11:$D$1510,$B17,'Lanç. Pessoal'!$B$11:$B$1510,">="&I$7,'Lanç. Pessoal'!$B$11:$B$1510,"<"&EDATE(I$7,1))) -> 0 | J17: =IF($B17="",0,SUMIFS('Lanç. Pessoal'!$F$11:$F$1510,'Lanç. Pessoal'!$D$11:$D$1510,$B17,'Lanç. Pessoal'!$B$11:$B$1510,">="&J$7,'Lanç. Pessoal'!$B$11:$B$1510,"<"&EDATE(J$7,1))) -> 0 | ... N17: =IF($B17="",0,SUMIFS('Lanç. Pessoal'!$F$11:$F$1510,'Lanç. Pessoal'!$D$11:$D$1510,$B17,'Lanç. Pessoal'!$B$11:$B$1510,">="&N$7,'Lanç. Pessoal'!$B$11:$B$1510,"<"&EDATE(N$7,1))) -> 0 | O17: =SUM(C17:N17) -> 0 | P17: =IFERROR(O17/'Dados'!$C$11,0) -> 0
B18: Total de entradas | C18: =SUM(C10:C17) -> 4546.63 | D18: =SUM(D10:D17) -> 4550.78 | E18: =SUM(E10:E17) -> 4944.68 | F18: =SUM(F10:F17) -> 4569.41 | G18: =SUM(G10:G17) -> 4553.22 | H18: =SUM(H10:H17) -> 4902 | I18: =SUM(I10:I17) -> 4560.59 | J18: =SUM(J10:J17) -> 4544.92 | ... P18: =SUM(P10:P17) -> 4636.1244
B19: ▼ SAÍDAS
B20: =IF('Config'!$G$8="","",'Config'!$G$8) -> Moradia | C20: =IF($B20="",0,SUMIFS('Lanç. Pessoal'!$F$11:$F$1510,'Lanç. Pessoal'!$D$11:$D$1510,$B20,'Lanç. Pessoal'!$B$11:$B$1510,">="&C$7,'Lanç. Pessoal'!$B$11:$B$1510,"<"&EDATE(C$7,1))) -> 1100 | D20: =IF($B20="",0,SUMIFS('Lanç. Pessoal'!$F$11:$F$1510,'Lanç. Pessoal'!$D$11:$D$1510,$B20,'Lanç. Pessoal'!$B$11:$B$1510,">="&D$7,'Lanç. Pessoal'!$B$11:$B$1510,"<"&EDATE(D$7,1))) -> 1100 | E20: =IF($B20="",0,SUMIFS('Lanç. Pessoal'!$F$11:$F$1510,'Lanç. Pessoal'!$D$11:$D$1510,$B20,'Lanç. Pessoal'!$B$11:$B$1510,">="&E$7,'Lanç. Pessoal'!$B$11:$B$1510,"<"&EDATE(E$7,1))) -> 1100 | F20: =IF($B20="",0,SUMIFS('Lanç. Pessoal'!$F$11:$F$1510,'Lanç. Pessoal'!$D$11:$D$1510,$B20,'Lanç. Pessoal'!$B$11:$B$1510,">="&F$7,'Lanç. Pessoal'!$B$11:$B$1510,"<"&EDATE(F$7,1))) -> 1100 | G20: =IF($B20="",0,SUMIFS('Lanç. Pessoal'!$F$11:$F$1510,'Lanç. Pessoal'!$D$11:$D$1510,$B20,'Lanç. Pessoal'!$B$11:$B$1510,">="&G$7,'Lanç. Pessoal'!$B$11:$B$1510,"<"&EDATE(G$7,1))) -> 1100 | H20: =IF($B20="",0,SUMIFS('Lanç. Pessoal'!$F$11:$F$1510,'Lanç. Pessoal'!$D$11:$D$1510,$B20,'Lanç. Pessoal'!$B$11:$B$1510,">="&H$7,'Lanç. Pessoal'!$B$11:$B$1510,"<"&EDATE(H$7,1))) -> 1100 | I20: =IF($B20="",0,SUMIFS('Lanç. Pessoal'!$F$11:$F$1510,'Lanç. Pessoal'!$D$11:$D$1510,$B20,'Lanç. Pessoal'!$B$11:$B$1510,">="&I$7,'Lanç. Pessoal'!$B$11:$B$1510,"<"&EDATE(I$7,1))) -> 1100 | J20: =IF($B20="",0,SUMIFS('Lanç. Pessoal'!$F$11:$F$1510,'Lanç. Pessoal'!$D$11:$D$1510,$B20,'Lanç. Pessoal'!$B$11:$B$1510,">="&J$7,'Lanç. Pessoal'!$B$11:$B$1510,"<"&EDATE(J$7,1))) -> 1100 | ... N20: =IF($B20="",0,SUMIFS('Lanç. Pessoal'!$F$11:$F$1510,'Lanç. Pessoal'!$D$11:$D$1510,$B20,'Lanç. Pessoal'!$B$11:$B$1510,">="&N$7,'Lanç. Pessoal'!$B$11:$B$1510,"<"&EDATE(N$7,1))) -> 0 | O20: =SUM(C20:N20) -> 9900 | P20: =IFERROR(O20/'Dados'!$C$11,0) -> 1100 | Q20: =IFERROR(O20/$O$36,0) -> 0.24364715
B21: =IF('Config'!$G$9="","",'Config'!$G$9) -> Contas da casa | C21: =IF($B21="",0,SUMIFS('Lanç. Pessoal'!$F$11:$F$1510,'Lanç. Pessoal'!$D$11:$D$1510,$B21,'Lanç. Pessoal'!$B$11:$B$1510,">="&C$7,'Lanç. Pessoal'!$B$11:$B$1510,"<"&EDATE(C$7,1))) -> 334.23 | D21: =IF($B21="",0,SUMIFS('Lanç. Pessoal'!$F$11:$F$1510,'Lanç. Pessoal'!$D$11:$D$1510,$B21,'Lanç. Pessoal'!$B$11:$B$1510,">="&D$7,'Lanç. Pessoal'!$B$11:$B$1510,"<"&EDATE(D$7,1))) -> 396.48 | E21: =IF($B21="",0,SUMIFS('Lanç. Pessoal'!$F$11:$F$1510,'Lanç. Pessoal'!$D$11:$D$1510,$B21,'Lanç. Pessoal'!$B$11:$B$1510,">="&E$7,'Lanç. Pessoal'!$B$11:$B$1510,"<"&EDATE(E$7,1))) -> 346.44 | F21: =IF($B21="",0,SUMIFS('Lanç. Pessoal'!$F$11:$F$1510,'Lanç. Pessoal'!$D$11:$D$1510,$B21,'Lanç. Pessoal'!$B$11:$B$1510,">="&F$7,'Lanç. Pessoal'!$B$11:$B$1510,"<"&EDATE(F$7,1))) -> 340.42 | G21: =IF($B21="",0,SUMIFS('Lanç. Pessoal'!$F$11:$F$1510,'Lanç. Pessoal'!$D$11:$D$1510,$B21,'Lanç. Pessoal'!$B$11:$B$1510,">="&G$7,'Lanç. Pessoal'!$B$11:$B$1510,"<"&EDATE(G$7,1))) -> 458.67 | H21: =IF($B21="",0,SUMIFS('Lanç. Pessoal'!$F$11:$F$1510,'Lanç. Pessoal'!$D$11:$D$1510,$B21,'Lanç. Pessoal'!$B$11:$B$1510,">="&H$7,'Lanç. Pessoal'!$B$11:$B$1510,"<"&EDATE(H$7,1))) -> 358.42 | I21: =IF($B21="",0,SUMIFS('Lanç. Pessoal'!$F$11:$F$1510,'Lanç. Pessoal'!$D$11:$D$1510,$B21,'Lanç. Pessoal'!$B$11:$B$1510,">="&I$7,'Lanç. Pessoal'!$B$11:$B$1510,"<"&EDATE(I$7,1))) -> 296.98 | J21: =IF($B21="",0,SUMIFS('Lanç. Pessoal'!$F$11:$F$1510,'Lanç. Pessoal'!$D$11:$D$1510,$B21,'Lanç. Pessoal'!$B$11:$B$1510,">="&J$7,'Lanç. Pessoal'!$B$11:$B$1510,"<"&EDATE(J$7,1))) -> 419.01 | ... N21: =IF($B21="",0,SUMIFS('Lanç. Pessoal'!$F$11:$F$1510,'Lanç. Pessoal'!$D$11:$D$1510,$B21,'Lanç. Pessoal'!$B$11:$B$1510,">="&N$7,'Lanç. Pessoal'!$B$11:$B$1510,"<"&EDATE(N$7,1))) -> 0 | O21: =SUM(C21:N21) -> 3240.56 | P21: =IFERROR(O21/'Dados'!$C$11,0) -> 360.06222 | Q21: =IFERROR(O21/$O$36,0) -> 0.079752848
B22: =IF('Config'!$G$10="","",'Config'!$G$10) -> Alimentação | C22: =IF($B22="",0,SUMIFS('Lanç. Pessoal'!$F$11:$F$1510,'Lanç. Pessoal'!$D$11:$D$1510,$B22,'Lanç. Pessoal'!$B$11:$B$1510,">="&C$7,'Lanç. Pessoal'!$B$11:$B$1510,"<"&EDATE(C$7,1))) -> 695.87 | D22: =IF($B22="",0,SUMIFS('Lanç. Pessoal'!$F$11:$F$1510,'Lanç. Pessoal'!$D$11:$D$1510,$B22,'Lanç. Pessoal'!$B$11:$B$1510,">="&D$7,'Lanç. Pessoal'!$B$11:$B$1510,"<"&EDATE(D$7,1))) -> 637.86 | E22: =IF($B22="",0,SUMIFS('Lanç. Pessoal'!$F$11:$F$1510,'Lanç. Pessoal'!$D$11:$D$1510,$B22,'Lanç. Pessoal'!$B$11:$B$1510,">="&E$7,'Lanç. Pessoal'!$B$11:$B$1510,"<"&EDATE(E$7,1))) -> 800.28 | F22: =IF($B22="",0,SUMIFS('Lanç. Pessoal'!$F$11:$F$1510,'Lanç. Pessoal'!$D$11:$D$1510,$B22,'Lanç. Pessoal'!$B$11:$B$1510,">="&F$7,'Lanç. Pessoal'!$B$11:$B$1510,"<"&EDATE(F$7,1))) -> 713.43 | G22: =IF($B22="",0,SUMIFS('Lanç. Pessoal'!$F$11:$F$1510,'Lanç. Pessoal'!$D$11:$D$1510,$B22,'Lanç. Pessoal'!$B$11:$B$1510,">="&G$7,'Lanç. Pessoal'!$B$11:$B$1510,"<"&EDATE(G$7,1))) -> 611.9 | H22: =IF($B22="",0,SUMIFS('Lanç. Pessoal'!$F$11:$F$1510,'Lanç. Pessoal'!$D$11:$D$1510,$B22,'Lanç. Pessoal'!$B$11:$B$1510,">="&H$7,'Lanç. Pessoal'!$B$11:$B$1510,"<"&EDATE(H$7,1))) -> 688.54 | I22: =IF($B22="",0,SUMIFS('Lanç. Pessoal'!$F$11:$F$1510,'Lanç. Pessoal'!$D$11:$D$1510,$B22,'Lanç. Pessoal'!$B$11:$B$1510,">="&I$7,'Lanç. Pessoal'!$B$11:$B$1510,"<"&EDATE(I$7,1))) -> 667.96 | J22: =IF($B22="",0,SUMIFS('Lanç. Pessoal'!$F$11:$F$1510,'Lanç. Pessoal'!$D$11:$D$1510,$B22,'Lanç. Pessoal'!$B$11:$B$1510,">="&J$7,'Lanç. Pessoal'!$B$11:$B$1510,"<"&EDATE(J$7,1))) -> 717.97 | ... N22: =IF($B22="",0,SUMIFS('Lanç. Pessoal'!$F$11:$F$1510,'Lanç. Pessoal'!$D$11:$D$1510,$B22,'Lanç. Pessoal'!$B$11:$B$1510,">="&N$7,'Lanç. Pessoal'!$B$11:$B$1510,"<"&EDATE(N$7,1))) -> 0 | O22: =SUM(C22:N22) -> 6161.08 | P22: =IFERROR(O22/'Dados'!$C$11,0) -> 684.56444 | Q22: =IFERROR(O22/$O$36,0) -> 0.15162925
B23: =IF('Config'!$G$11="","",'Config'!$G$11) -> Transporte | C23: =IF($B23="",0,SUMIFS('Lanç. Pessoal'!$F$11:$F$1510,'Lanç. Pessoal'!$D$11:$D$1510,$B23,'Lanç. Pessoal'!$B$11:$B$1510,">="&C$7,'Lanç. Pessoal'!$B$11:$B$1510,"<"&EDATE(C$7,1))) -> 287.17 | D23: =IF($B23="",0,SUMIFS('Lanç. Pessoal'!$F$11:$F$1510,'Lanç. Pessoal'!$D$11:$D$1510,$B23,'Lanç. Pessoal'!$B$11:$B$1510,">="&D$7,'Lanç. Pessoal'!$B$11:$B$1510,"<"&EDATE(D$7,1))) -> 267.73 | E23: =IF($B23="",0,SUMIFS('Lanç. Pessoal'!$F$11:$F$1510,'Lanç. Pessoal'!$D$11:$D$1510,$B23,'Lanç. Pessoal'!$B$11:$B$1510,">="&E$7,'Lanç. Pessoal'!$B$11:$B$1510,"<"&EDATE(E$7,1))) -> 285.21 | F23: =IF($B23="",0,SUMIFS('Lanç. Pessoal'!$F$11:$F$1510,'Lanç. Pessoal'!$D$11:$D$1510,$B23,'Lanç. Pessoal'!$B$11:$B$1510,">="&F$7,'Lanç. Pessoal'!$B$11:$B$1510,"<"&EDATE(F$7,1))) -> 989.03 | G23: =IF($B23="",0,SUMIFS('Lanç. Pessoal'!$F$11:$F$1510,'Lanç. Pessoal'!$D$11:$D$1510,$B23,'Lanç. Pessoal'!$B$11:$B$1510,">="&G$7,'Lanç. Pessoal'!$B$11:$B$1510,"<"&EDATE(G$7,1))) -> 267.33 | H23: =IF($B23="",0,SUMIFS('Lanç. Pessoal'!$F$11:$F$1510,'Lanç. Pessoal'!$D$11:$D$1510,$B23,'Lanç. Pessoal'!$B$11:$B$1510,">="&H$7,'Lanç. Pessoal'!$B$11:$B$1510,"<"&EDATE(H$7,1))) -> 276.74 | I23: =IF($B23="",0,SUMIFS('Lanç. Pessoal'!$F$11:$F$1510,'Lanç. Pessoal'!$D$11:$D$1510,$B23,'Lanç. Pessoal'!$B$11:$B$1510,">="&I$7,'Lanç. Pessoal'!$B$11:$B$1510,"<"&EDATE(I$7,1))) -> 287.7 | J23: =IF($B23="",0,SUMIFS('Lanç. Pessoal'!$F$11:$F$1510,'Lanç. Pessoal'!$D$11:$D$1510,$B23,'Lanç. Pessoal'!$B$11:$B$1510,">="&J$7,'Lanç. Pessoal'!$B$11:$B$1510,"<"&EDATE(J$7,1))) -> 729.29 | ... N23: =IF($B23="",0,SUMIFS('Lanç. Pessoal'!$F$11:$F$1510,'Lanç. Pessoal'!$D$11:$D$1510,$B23,'Lanç. Pessoal'!$B$11:$B$1510,">="&N$7,'Lanç. Pessoal'!$B$11:$B$1510,"<"&EDATE(N$7,1))) -> 0 | O23: =SUM(C23:N23) -> 3654.71 | P23: =IFERROR(O23/'Dados'!$C$11,0) -> 406.07889 | Q23: =IFERROR(O23/$O$36,0) -> 0.089945421
