Workbook

Sheet Início
B1: 🏠 Início | C1: 📊 Painel | D1: 📝 Lançamentos | F1: 💳 Orçamento | H1: 📅 Resumo Anual | J1: 🎯 Metas | L1: ⚙ Config
B3: Finanças em Dia — Pessoal
B4: Controle financeiro pessoal e doméstico • Excel e Google Sheets
B5: Bem-vindo(a)! Esta planilha organiza suas finanças do jeito mais simples: você só LANÇA os valores e todo o resto — resumos, gráficos, alertas e metas — é calculado automaticamente. Use o Painel para enxergar para onde o dinheiro vai e a aba Metas para transformar sonhos em planos.
B7: 🚀 COMECE EM 5 MINUTOS
B8: 1 | C8: Em ⚙ Config: confira o ANO, escreva seu nome e renomeie as categorias, se quiser.
B9: 2 | C9: Em 💳 Orçamento: informe a renda prevista e quanto pretende gastar em cada categoria.
B10: 3 | C10: Em 🎯 Metas: cadastre seus objetivos (reserva de emergência, viagem, carro...).
B11: 4 | C11: No dia a dia: registre cada entrada e saída em 📝 Lançamentos — escolha a categoria no menu suspenso.
B12: 5 | C12: Abra o 📊 Painel, escolha o mês e veja gráficos, alertas e a evolução das suas metas.
B14: 🗺 MAPA DA PLANILHA — clique no botão para navegar
B15: 📊 Painel | E15: Cartões, gráficos e alertas do mês escolhido: entradas, saídas, saldo e poupança.
B16: 📝 Lançamentos | E16: Registro de todas as entradas e saídas (tipo automático pela categoria).
B17: 💳 Orçamento | E17: Planejado × realizado por categoria, com barras de progresso e alertas.
B18: 📅 Resumo Anual | E18: Quadro mês a mês por categoria (entradas e saídas), com mapa de calor.
B19: 🎯 Metas | E19: Objetivos de economia, aporte mensal necessário e reserva de emergência.
B20: ⚙ Config | E20: Ano, nome, categorias, formas de pagamento e meta de poupança.
B22: 🎨 LEGENDA DE CORES
B23: Você preenche | D23: Fórmula (automático) | F23: Positivo / bom | H23: Atenção | J23: Negativo / alerta | L23: Informação
B25: 💡 DICAS IMPORTANTES
B26: • Google Sheets: envie o arquivo .xlsx para o Google Drive e abra com o Google Planilhas (ou Arquivo ▸ Importar). Os menus, gráficos, listas suspensas e cores funcionam igualmente.
B27: • Digite sempre valores POSITIVOS. Se a categoria for de entrada, o valor soma; se for de saída, subtrai — o tipo é automático.
B28: • Para começar um novo ano: salve uma cópia do arquivo, apague os lançamentos (colunas amarelas) e mude o ano em Config.
B29: • Não insira/apague linhas dentro das tabelas de fórmulas. Para ver mais lançamentos, use os filtros do cabeçalho; há espaço para 1500 linhas.
B30: • Cada aba tem botões de navegação no topo. Se algo parecer estranho, confira a faixa de VERIFICAÇÃO no topo de Lançamentos.
B32: Planilha educativa de organização financeira. Valores e exemplos são fictícios.

Sheet Painel
B1: 🏠 Início | C1: 📊 Painel | D1: 📝 Lançamentos | F1: 💳 Orçamento | H1: 📅 Resumo Anual | J1: 🎯 Metas | L1: ⚙ Config
B3: ="📊 Painel — "&'Config'!$C$8 -> 📊 Painel — Minhas Finanças
B4: Escolha o mês no menu suspenso: cartões, gráficos e alertas se atualizam sozinhos.
B5: 📅 Mês de análise | D5: =INDEX('Config'!$K$6:$K$17,MAX(1,'Dados'!$C$8)) -> Outubro | G5: Ano de referência | I5: ='Config'!$C$6 -> 2026 | J5: ← o ano e a meta de poupança ficam na aba Config
B7: ENTRADAS DO MÊS | D7: SAÍDAS DO MÊS | F7: SALDO DO MÊS | H7: TAXA DE POUPANÇA | J7: SALDO ACUMULADO | L7: MAIOR GASTO DO MÊS
B8: =INDEX('Resumo Anual'!$C$16:$N$16,'Dados'!$C$6) -> 0 | D8: =INDEX('Resumo Anual'!$C$34:$N$34,'Dados'!$C$6) -> 0 | F8: =INDEX('Resumo Anual'!$C$16:$N$16,'Dados'!$C$6)-INDEX('Resumo Anual'!$C$34:$N$34,'Dados'!$C$6) -> 0 | H8: =IF(INDEX('Resumo Anual'!$C$16:$N$16,'Dados'!$C$6)=0,0,INDEX('Resumo Anual'!$C$37:$N$37,'Dados'!$C$6)) -> 0 | J8: =INDEX('Resumo Anual'!$C$36:$N$36,'Dados'!$C$6) -> 0 | L8: ='Dados'!$J$16 -> —
B9: =IF('Dados'!$C$6=1,"—",IF(INDEX('Resumo Anual'!$C$16:$N$16,'Dados'!$C$6-1)=0,"—",IF(INDEX('Resumo Anual'!$C$16:$N$16,'Dados'!$C$6)>=INDEX('Resumo Anual'!$C$16:$N$16,'Dados'!$C$6-1),"▲ ","▼ ")&TEXT(ABS(INDEX('Resumo Anual'!$C$16:$N$16,'Dados'!$C$6)/INDEX('Resumo Anual'!$C$16:$N$16,'Dados'!$C$6-1)-1),"0%")&" vs mês anterior")) -> — | D9: =IF('Dados'!$C$6=1,"—",IF(INDEX('Resumo Anual'!$C$34:$N$34,'Dados'!$C$6-1)=0,"—",IF(INDEX('Resumo Anual'!$C$34:$N$34,'Dados'!$C$6)>=INDEX('Resumo Anual'!$C$34:$N$34,'Dados'!$C$6-1),"▲ ","▼ ")&TEXT(ABS(INDEX('Resumo Anual'!$C$34:$N$34,'Dados'!$C$6)/INDEX('Resumo Anual'!$C$34:$N$34,'Dados'!$C$6-1)-1),"0%")&" vs mês anterior")) -> — | F9: =IF(INDEX('Resumo Anual'!$C$16:$N$16,'Dados'!$C$6)-INDEX('Resumo Anual'!$C$34:$N$34,'Dados'!$C$6)>=0,"Sobrou dinheiro ✓","Gastou mais do que ganhou") -> Sobrou dinheiro ✓ | H9: ="Meta: "&TEXT('Config'!$C$9,"0%") -> Meta: 20% | J9: no ano, até o mês escolhido | L9: ='Dados'!$K$16 -> 0
B43: 🎯 METAS DE ECONOMIA
B44: Meta | E44: Guardado | G44: Valor alvo | I44: % | J44: Progresso | M44: Situação
B45: =IF('Metas'!$B$6="","",'Metas'!$B$6) | E45: =IF('Metas'!$B$6="","",'Metas'!$G$6) | G45: =IF('Metas'!$B$6="","",'Metas'!$C$6) | I45: =IF('Metas'!$H$6="","",'Metas'!$H$6) | J45: =IF('Metas'!$I$6="","",'Metas'!$I$6) | M45: =IF('Metas'!$B$6="","",'Metas'!$M$6)
B46: =IF('Metas'!$B$7="","",'Metas'!$B$7) | E46: =IF('Metas'!$B$7="","",'Metas'!$G$7) | G46: =IF('Metas'!$B$7="","",'Metas'!$C$7) | I46: =IF('Metas'!$H$7="","",'Metas'!$H$7) | J46: =IF('Metas'!$I$7="","",'Metas'!$I$7) | M46: =IF('Metas'!$B$7="","",'Metas'!$M$7)
B47: =IF('Metas'!$B$8="","",'Metas'!$B$8) | E47: =IF('Metas'!$B$8="","",'Metas'!$G$8) | G47: =IF('Metas'!$B$8="","",'Metas'!$C$8) | I47: =IF('Metas'!$H$8="","",'Metas'!$H$8) | J47: =IF('Metas'!$I$8="","",'Metas'!$I$8) | M47: =IF('Metas'!$B$8="","",'Metas'!$M$8)
B48: =IF('Metas'!$B$9="","",'Metas'!$B$9) | E48: =IF('Metas'!$B$9="","",'Metas'!$G$9) | G48: =IF('Metas'!$B$9="","",'Metas'!$C$9) | I48: =IF('Metas'!$H$9="","",'Metas'!$H$9) | J48: =IF('Metas'!$I$9="","",'Metas'!$I$9) | M48: =IF('Metas'!$B$9="","",'Metas'!$M$9)
B49: =IF('Metas'!$B$10="","",'Metas'!$B$10) | E49: =IF('Metas'!$B$10="","",'Metas'!$G$10) | G49: =IF('Metas'!$B$10="","",'Metas'!$C$10) | I49: =IF('Metas'!$H$10="","",'Metas'!$H$10) | J49: =IF('Metas'!$I$10="","",'Metas'!$I$10) | M49: =IF('Metas'!$B$10="","",'Metas'!$M$10)
B51: Veja todas as metas e o simulador de aportes na aba Metas.
B52: 🔔 ALERTAS E INSIGHTS DO MÊS
B53: =IF(AND(INDEX('Resumo Anual'!$C$16:$N$16,'Dados'!$C$6)=0,INDEX('Resumo Anual'!$C$34:$N$34,'Dados'!$C$6)=0),"ℹ Ainda não há lançamentos neste mês.",IF((INDEX('Resumo Anual'!$C$16:$N$16,'Dados'!$C$6)-INDEX('Resumo Anual'!$C$34:$N$34,'Dados'!$C$6))<0,"⚠ Você gastou R$ "&FIXED(-(INDEX('Resumo Anual'!$C$16:$N$16,'Dados'!$C$6)-INDEX('Resumo Anual'!$C$34:$N$34,'Dados'!$C$6)),2)&" a mais do que ganhou neste mês.","✓ Mês no azul: sobraram R$ "&FIXED((INDEX('Resumo Anual'!$C$16:$N$16,'Dados'!$C$6)-INDEX('Resumo Anual'!$C$34:$N$34,'Dados'!$C$6)),2)&" depois de todas as saídas.")) -> ℹ Ainda não há lançamentos neste mês.
B54: =IF('Orçamento'!$C$26=0,"ℹ Defina o orçamento por categoria na aba Orçamento para receber alertas de gastos.",IF('Dados'!$C$11=0,"✓ Nenhuma categoria acima do orçamento neste mês.","⚠ "&'Dados'!$C$11&" categoria(s) acima do orçamento planejado — veja a aba Orçamento.")) -> ℹ Defina o orçamento por categoria na aba Orçamento para receber alertas de gastos.
B55: =IF(INDEX('Resumo Anual'!$C$16:$N$16,'Dados'!$C$6)=0,"ℹ Registre suas entradas do mês para calcular a taxa de poupança.",IF(INDEX('Resumo Anual'!$C$37:$N$37,'Dados'!$C$6)>='Config'!$C$9,"✓ Meta de poupança atingida: "&TEXT(INDEX('Resumo Anual'!$C$37:$N$37,'Dados'!$C$6),"0%")&" (meta "&TEXT('Config'!$C$9,"0%")&").","⚠ Taxa de poupança de "&TEXT(INDEX('Resumo Anual'!$C$37:$N$37,'Dados'!$C$6),"0%")&", abaixo da meta de "&TEXT('Config'!$C$9,"0%")&".")) -> ℹ Registre suas entradas do mês para calcular a taxa de poupança.

Sheet Lançamentos
B1: 🏠 Início | C1: 📊 Painel | D1: 📝 Lançamentos | E1: 💳 Orçamento | F1: 📅 Resumo Anual | H1: 🎯 Metas | I1: ⚙ Config
B3: 📝 Lançamentos — registre cada entrada e saída
B4: Preencha as colunas amarelas. Valor sempre positivo; o Tipo (Entrada/Saída) é automático pela categoria.
B5: ENTRADAS NO ANO | D5: SAÍDAS NO ANO | E5: SALDO DO ANO | G5: VERIFICAÇÃO AUTOMÁTICA
B6: =SUMIFS('Lançamentos'!$F$9:$F$1508,'Lançamentos'!$G$9:$G$1508,"Entrada",'Lançamentos'!$B$9:$B$1508,">="&DATE('Config'!$C$6,1,1),'Lançamentos'!$B$9:$B$1508,"<"&DATE('Config'!$C$6+1,1,1)) -> 0 | D6: =SUMIFS('Lançamentos'!$F$9:$F$1508,'Lançamentos'!$G$9:$G$1508,"Saída",'Lançamentos'!$B$9:$B$1508,">="&DATE('Config'!$C$6,1,1),'Lançamentos'!$B$9:$B$1508,"<"&DATE('Config'!$C$6+1,1,1)) -> 0 | E6: =B6-D6 -> 0 | G6: =IF(SUMPRODUCT(('Lançamentos'!$F$9:$F$1508>0)*('Lançamentos'!$D$9:$D$1508=""))>0,"⚠ "&SUMPRODUCT(('Lançamentos'!$F$9:$F$1508>0)*('Lançamentos'!$D$9:$D$1508=""))&" lançamento(s) sem categoria — não entram nos painéis",IF(COUNTIF('Lançamentos'!$G$9:$G$1508,"Verificar")>0,"⚠ "&COUNTIF('Lançamentos'!$G$9:$G$1508,"Verificar")&" lançamento(s) com categoria inválida (coluna Tipo = Verificar)",IF((COUNT('Lançamentos'!$F$9:$F$1508)-COUNTIFS('Lançamentos'!$B$9:$B$1508,">="&DATE('Config'!$C$6,1,1),'Lançamentos'!$B$9:$B$1508,"<"&DATE('Config'!$C$6+1,1,1),'Lançamentos'!$F$9:$F$1508,">0"))>0,"⚠ "&(COUNT('Lançamentos'!$F$9:$F$1508)-COUNTIFS('Lançamentos'!$B$9:$B$1508,">="&DATE('Config'!$C$6,1,1),'Lançamentos'!$B$9:$B$1508,"<"&DATE('Config'!$C$6+1,1,1),'Lançamentos'!$F$9:$F$1508,">0"))&" lançamento(s) sem data ou fora de "&'Config'!$C$6&" — não entram nos painéis","✓ Tudo certo: "&COUNT('Lançamentos'!$F$9:$F$1508)&" lançamento(s) registrados"))) -> ✓ Tudo certo: 0 lançamento(s) registrados
B8: Data | C8: Descrição | D8: Categoria | E8: Forma de pagamento | F8: Valor (R$) | G8: Tipo | H8: Meta (opcional) | I8: Observação
G9: =IF($D9="","",IF(COUNTIF('Config'!$E$6:$E$13,$D9)>0,"Entrada",IF(COUNTIF('Config'!$G$6:$G$21,$D9)>0,"Saída","Verificar")))
G10: =IF($D10="","",IF(COUNTIF('Config'!$E$6:$E$13,$D10)>0,"Entrada",IF(COUNTIF('Config'!$G$6:$G$21,$D10)>0,"Saída","Verificar")))
G11: =IF($D11="","",IF(COUNTIF('Config'!$E$6:$E$13,$D11)>0,"Entrada",IF(COUNTIF('Config'!$G$6:$G$21,$D11)>0,"Saída","Verificar")))
G12: =IF($D12="","",IF(COUNTIF('Config'!$E$6:$E$13,$D12)>0,"Entrada",IF(COUNTIF('Config'!$G$6:$G$21,$D12)>0,"Saída","Verificar")))
G13: =IF($D13="","",IF(COUNTIF('Config'!$E$6:$E$13,$D13)>0,"Entrada",IF(COUNTIF('Config'!$G$6:$G$21,$D13)>0,"Saída","Verificar")))
G14: =IF($D14="","",IF(COUNTIF('Config'!$E$6:$E$13,$D14)>0,"Entrada",IF(COUNTIF('Config'!$G$6:$G$21,$D14)>0,"Saída","Verificar")))
G15: =IF($D15="","",IF(COUNTIF('Config'!$E$6:$E$13,$D15)>0,"Entrada",IF(COUNTIF('Config'!$G$6:$G$21,$D15)>0,"Saída","Verificar")))
G16: =IF($D16="","",IF(COUNTIF('Config'!$E$6:$E$13,$D16)>0,"Entrada",IF(COUNTIF('Config'!$G$6:$G$21,$D16)>0,"Saída","Verificar")))
G17: =IF($D17="","",IF(COUNTIF('Config'!$E$6:$E$13,$D17)>0,"Entrada",IF(COUNTIF('Config'!$G$6:$G$21,$D17)>0,"Saída","Verificar")))
G18: =IF($D18="","",IF(COUNTIF('Config'!$E$6:$E$13,$D18)>0,"Entrada",IF(COUNTIF('Config'!$G$6:$G$21,$D18)>0,"Saída","Verificar")))
G19: =IF($D19="","",IF(COUNTIF('Config'!$E$6:$E$13,$D19)>0,"Entrada",IF(COUNTIF('Config'!$G$6:$G$21,$D19)>0,"Saída","Verificar")))
G20: =IF($D20="","",IF(COUNTIF('Config'!$E$6:$E$13,$D20)>0,"Entrada",IF(COUNTIF('Config'!$G$6:$G$21,$D20)>0,"Saída","Verificar")))
... G1508: =IF($D1508="","",IF(COUNTIF('Config'!$E$6:$E$13,$D1508)>0,"Entrada",IF(COUNTIF('Config'!$G$6:$G$21,$D1508)>0,"Saída","Verificar")))

Sheet Orçamento
B1: 🏠 Início | C1: 📊 Painel | D1: 📝 Lançamentos | E1: 💳 Orçamento | F1: 📅 Resumo Anual | G1: 🎯 Metas | H1: ⚙ Config
B3: 💳 Orçamento mensal — planejado × realizado
B4: Defina quanto pretende gastar em cada categoria. O 'realizado' vem dos lançamentos do mês escolhido.
B5: 📅 Mês de análise: | C5: =INDEX('Config'!$K$6:$K$17,MAX(1,'Dados'!$C$8)) -> Outubro | D5: ← escolha o mês no menu suspenso. Os valores planejados (amarelo) valem para todos os meses.
B7: Categoria | C7: Planejado (mês) | D7: Realizado | E7: Diferença | F7: % usado | G7: Progresso | H7: Situação
B8: Renda do mês (entradas) | C8: 0 | D8: =INDEX('Resumo Anual'!$C$16:$N$16,'Dados'!$C$7) -> 0 | E8: =D8-C8 -> 0 | F8: =IF(C8>0,D8/C8,"") | G8: =IF(F8="","",REPT("█",MIN(22,ROUND(F8*20,0)))) | H8: =IF(C8=0,"—",IF(D8>=C8,"✓ Meta batida",IF(D8>=C8*0.8,"⚠ Quase lá","✖ Abaixo"))) -> —
B9: DESPESAS POR CATEGORIA
B10: =IF('Config'!$G$6="","",'Config'!$G$6) -> Moradia | C10: 0 | D10: =IF(B10="",0,INDEX('Resumo Anual'!$C$18:$N$18,'Dados'!$C$7)) -> 0 | E10: =C10-D10 -> 0 | F10: =IF(C10>0,D10/C10,"") | G10: =IF(F10="","",REPT("█",MIN(22,ROUND(F10*20,0)))) | H10: =IF(C10=0,IF(D10>0,"Sem orçamento","—"),IF(D10>C10,"✖ Estourou",IF(D10>=C10*0.8,"⚠ Atenção","✓ OK"))) -> —
B11: =IF('Config'!$G$7="","",'Config'!$G$7) -> Contas da casa | C11: 0 | D11: =IF(B11="",0,INDEX('Resumo Anual'!$C$19:$N$19,'Dados'!$C$7)) -> 0 | E11: =C11-D11 -> 0 | F11: =IF(C11>0,D11/C11,"") | G11: =IF(F11="","",REPT("█",MIN(22,ROUND(F11*20,0)))) | H11: =IF(C11=0,IF(D11>0,"Sem orçamento","—"),IF(D11>C11,"✖ Estourou",IF(D11>=C11*0.8,"⚠ Atenção","✓ OK"))) -> —
B12: =IF('Config'!$G$8="","",'Config'!$G$8) -> Alimentação | C12: 0 | D12: =IF(B12="",0,INDEX('Resumo Anual'!$C$20:$N$20,'Dados'!$C$7)) -> 0 | E12: =C12-D12 -> 0 | F12: =IF(C12>0,D12/C12,"") | G12: =IF(F12="","",REPT("█",MIN(22,ROUND(F12*20,0)))) | H12: =IF(C12=0,IF(D12>0,"Sem orçamento","—"),IF(D12>C12,"✖ Estourou",IF(D12>=C12*0.8,"⚠ Atenção","✓ OK"))) -> —
B13: =IF('Config'!$G$9="","",'Config'!$G$9) -> Transporte | C13: 0 | D13: =IF(B13="",0,INDEX('Resumo Anual'!$C$21:$N$21,'Dados'!$C$7)) -> 0 | E13: =C13-D13 -> 0 | F13: =IF(C13>0,D13/C13,"") | G13: =IF(F13="","",REPT("█",MIN(22,ROUND(F13*20,0)))) | H13: =IF(C13=0,IF(D13>0,"Sem orçamento","—"),IF(D13>C13,"✖ Estourou",IF(D13>=C13*0.8,"⚠ Atenção","✓ OK"))) -> —
B14: =IF('Config'!$G$10="","",'Config'!$G$10) -> Saúde | C14: 0 | D14: =IF(B14="",0,INDEX('Resumo Anual'!$C$22:$N$22,'Dados'!$C$7)) -> 0 | E14: =C14-D14 -> 0 | F14: =IF(C14>0,D14/C14,"") | G14: =IF(F14="","",REPT("█",MIN(22,ROUND(F14*20,0)))) | H14: =IF(C14=0,IF(D14>0,"Sem orçamento","—"),IF(D14>C14,"✖ Estourou",IF(D14>=C14*0.8,"⚠ Atenção","✓ OK"))) -> —
B15: =IF('Config'!$G$11="","",'Config'!$G$11) -> Educação | C15: 0 | D15: =IF(B15="",0,INDEX('Resumo Anual'!$C$23:$N$23,'Dados'!$C$7)) -> 0 | E15: =C15-D15 -> 0 | F15: =IF(C15>0,D15/C15,"") | G15: =IF(F15="","",REPT("█",MIN(22,ROUND(F15*20,0)))) | H15: =IF(C15=0,IF(D15>0,"Sem orçamento","—"),IF(D15>C15,"✖ Estourou",IF(D15>=C15*0.8,"⚠ Atenção","✓ OK"))) -> —
B16: =IF('Config'!$G$12="","",'Config'!$G$12) -> Lazer | C16: 0 | D16: =IF(B16="",0,INDEX('Resumo Anual'!$C$24:$N$24,'Dados'!$C$7)) -> 0 | E16: =C16-D16 -> 0 | F16: =IF(C16>0,D16/C16,"") | G16: =IF(F16="","",REPT("█",MIN(22,ROUND(F16*20,0)))) | H16: =IF(C16=0,IF(D16>0,"Sem orçamento","—"),IF(D16>C16,"✖ Estourou",IF(D16>=C16*0.8,"⚠ Atenção","✓ OK"))) -> —
B17: =IF('Config'!$G$13="","",'Config'!$G$13) -> Vestuário | C17: 0 | D17: =IF(B17="",0,INDEX('Resumo Anual'!$C$25:$N$25,'Dados'!$C$7)) -> 0 | E17: =C17-D17 -> 0 | F17: =IF(C17>0,D17/C17,"") | G17: =IF(F17="","",REPT("█",MIN(22,ROUND(F17*20,0)))) | H17: =IF(C17=0,IF(D17>0,"Sem orçamento","—"),IF(D17>C17,"✖ Estourou",IF(D17>=C17*0.8,"⚠ Atenção","✓ OK"))) -> —
B18: =IF('Config'!$G$14="","",'Config'!$G$14) -> Assinaturas | C18: 0 | D18: =IF(B18="",0,INDEX('Resumo Anual'!$C$26:$N$26,'Dados'!$C$7)) -> 0 | E18: =C18-D18 -> 0 | F18: =IF(C18>0,D18/C18,"") | G18: =IF(F18="","",REPT("█",MIN(22,ROUND(F18*20,0)))) | H18: =IF(C18=0,IF(D18>0,"Sem orçamento","—"),IF(D18>C18,"✖ Estourou",IF(D18>=C18*0.8,"⚠ Atenção","✓ OK"))) -> —
B19: =IF('Config'!$G$15="","",'Config'!$G$15) -> Cuidados pessoais | C19: 0 | D19: =IF(B19="",0,INDEX('Resumo Anual'!$C$27:$N$27,'Dados'!$C$7)) -> 0 | E19: =C19-D19 -> 0 | F19: =IF(C19>0,D19/C19,"") | G19: =IF(F19="","",REPT("█",MIN(22,ROUND(F19*20,0)))) | H19: =IF(C19=0,IF(D19>0,"Sem orçamento","—"),IF(D19>C19,"✖ Estourou",IF(D19>=C19*0.8,"⚠ Atenção","✓ OK"))) -> —
B20: =IF('Config'!$G$16="","",'Config'!$G$16) -> Pets | C20: 0 | D20: =IF(B20="",0,INDEX('Resumo Anual'!$C$28:$N$28,'Dados'!$C$7)) -> 0 | E20: =C20-D20 -> 0 | F20: =IF(C20>0,D20/C20,"") | G20: =IF(F20="","",REPT("█",MIN(22,ROUND(F20*20,0)))) | H20: =IF(C20=0,IF(D20>0,"Sem orçamento","—"),IF(D20>C20,"✖ Estourou",IF(D20>=C20*0.8,"⚠ Atenção","✓ OK"))) -> —
B21: =IF('Config'!$G$17="","",'Config'!$G$17) -> Presentes e doações | C21: 0 | D21: =IF(B21="",0,INDEX('Resumo Anual'!$C$29:$N$29,'Dados'!$C$7)) -> 0 | E21: =C21-D21 -> 0 | F21: =IF(C21>0,D21/C21,"") | G21: =IF(F21="","",REPT("█",MIN(22,ROUND(F21*20,0)))) | H21: =IF(C21=0,IF(D21>0,"Sem orçamento","—"),IF(D21>C21,"✖ Estourou",IF(D21>=C21*0.8,"⚠ Atenção","✓ OK"))) -> —
B22: =IF('Config'!$G$18="","",'Config'!$G$18) -> Dívidas e financiamentos | C22: 0 | D22: =IF(B22="",0,INDEX('Resumo Anual'!$C$30:$N$30,'Dados'!$C$7)) -> 0 | E22: =C22-D22 -> 0 | F22: =IF(C22>0,D22/C22,"") | G22: =IF(F22="","",REPT("█",MIN(22,ROUND(F22*20,0)))) | H22: =IF(C22=0,IF(D22>0,"Sem orçamento","—"),IF(D22>C22,"✖ Estourou",IF(D22>=C22*0.8,"⚠ Atenção","✓ OK"))) -> —
B23: =IF('Config'!$G$19="","",'Config'!$G$19) -> Reserva e Metas | C23: 0 | D23: =IF(B23="",0,INDEX('Resumo Anual'!$C$31:$N$31,'Dados'!$C$7)) -> 0 | E23: =D23-C23 -> 0 | F23: =IF(C23>0,D23/C23,"") | G23: =IF(F23="","",REPT("█",MIN(22,ROUND(F23*20,0)))) | H23: =IF(C23=0,"—",IF(D23>=C23,"✓ Meta batida",IF(D23>=C23*0.8,"⚠ Quase lá","✖ Abaixo"))) -> —
B24: =IF('Config'!$G$20="","",'Config'!$G$20) -> Impostos pessoais | C24: 0 | D24: =IF(B24="",0,INDEX('Resumo Anual'!$C$32:$N$32,'Dados'!$C$7)) -> 0 | E24: =C24-D24 -> 0 | F24: =IF(C24>0,D24/C24,"") | G24: =IF(F24="","",REPT("█",MIN(22,ROUND(F24*20,0)))) | H24: =IF(C24=0,IF(D24>0,"Sem orçamento","—"),IF(D24>C24,"✖ Estourou",IF(D24>=C24*0.8,"⚠ Atenção","✓ OK"))) -> —
B25: =IF('Config'!$G$21="","",'Config'!$G$21) -> Outros | C25: 0 | D25: =IF(B25="",0,INDEX('Resumo Anual'!$C$33:$N$33,'Dados'!$C$7)) -> 0 | E25: =C25-D25 -> 0 | F25: =IF(C25>0,D25/C25,"") | G25: =IF(F25="","",REPT("█",MIN(22,ROUND(F25*20,0)))) | H25: =IF(C25=0,IF(D25>0,"Sem orçamento","—"),IF(D25>C25,"✖ Estourou",IF(D25>=C25*0.8,"⚠ Atenção","✓ OK"))) -> —
B26: TOTAL DAS DESPESAS | C26: =SUM(C10:C25) -> 0 | D26: =SUM(D10:D25) -> 0 | E26: =C26-D26 -> 0 | F26: =IF(C26>0,D26/C26,"") | G26: =IF(F26="","",REPT("█",MIN(22,ROUND(F26*20,0)))) | H26: =IF(C26=0,"—",IF(D26>C26,"✖ Estourou",IF(D26>=C26*0.8,"⚠ Atenção","✓ OK"))) -> —
B27: SALDO (renda − despesas) | C27: =C8-C26 -> 0 | D27: =D8-D26 -> 0 | E27: =D27-C27 -> 0

Sheet Resumo Anual
B1: 🏠 Início | C1: 📊 Painel | E1: 📝 Lançamentos | H1: 💳 Orçamento | K1: 📅 Resumo Anual | N1: 🎯 Metas | P1: ⚙ Config
B3: 📅 Resumo anual — entradas e saídas por mês
B4: Totalizado automaticamente a partir da aba de lançamentos. Cores destacam saldos positivos e negativos.
C5: =DATE('Config'!$C$6,1,1) -> 46023 | D5: =DATE('Config'!$C$6,2,1) -> 46054 | E5: =DATE('Config'!$C$6,3,1) -> 46082 | F5: =DATE('Config'!$C$6,4,1) -> 46113 | G5: =DATE('Config'!$C$6,5,1) -> 46143 | H5: =DATE('Config'!$C$6,6,1) -> 46174 | I5: =DATE('Config'!$C$6,7,1) -> 46204 | J5: =DATE('Config'!$C$6,8,1) -> 46235 | K5: =DATE('Config'!$C$6,9,1) -> 46266 | L5: =DATE('Config'!$C$6,10,1) -> 46296 | M5: =DATE('Config'!$C$6,11,1) -> 46327 | N5: =DATE('Config'!$C$6,12,1) -> 46357
B6: Categoria | C6: =INDEX('Config'!$L$6:$L$17,1) -> Jan | D6: =INDEX('Config'!$L$6:$L$17,2) -> Fev | E6: =INDEX('Config'!$L$6:$L$17,3) -> Mar | F6: =INDEX('Config'!$L$6:$L$17,4) -> Abr | G6: =INDEX('Config'!$L$6:$L$17,5) -> Mai | H6: =INDEX('Config'!$L$6:$L$17,6) -> Jun | I6: =INDEX('Config'!$L$6:$L$17,7) -> Jul | J6: =INDEX('Config'!$L$6:$L$17,8) -> Ago | K6: =INDEX('Config'!$L$6:$L$17,9) -> Set | L6: =INDEX('Config'!$L$6:$L$17,10) -> Out | M6: =INDEX('Config'!$L$6:$L$17,11) -> Nov | N6: =INDEX('Config'!$L$6:$L$17,12) -> Dez | O6: Total | P6: Média/mês | Q6: % das saídas
B7: ▲ ENTRADAS
B8: =IF('Config'!$E$6="","",'Config'!$E$6) -> Salário | C8: =IF($B8="",0,SUMIFS('Lançamentos'!$F$9:$F$1508,'Lançamentos'!$D$9:$D$1508,$B8,'Lançamentos'!$B$9:$B$1508,">="&C$5,'Lançamentos'!$B$9:$B$1508,"<"&EDATE(C$5,1))) -> 0 | D8: =IF($B8="",0,SUMIFS('Lançamentos'!$F$9:$F$1508,'Lançamentos'!$D$9:$D$1508,$B8,'Lançamentos'!$B$9:$B$1508,">="&D$5,'Lançamentos'!$B$9:$B$1508,"<"&EDATE(D$5,1))) -> 0 | E8: =IF($B8="",0,SUMIFS('Lançamentos'!$F$9:$F$1508,'Lançamentos'!$D$9:$D$1508,$B8,'Lançamentos'!$B$9:$B$1508,">="&E$5,'Lançamentos'!$B$9:$B$1508,"<"&EDATE(E$5,1))) -> 0 | F8: =IF($B8="",0,SUMIFS('Lançamentos'!$F$9:$F$1508,'Lançamentos'!$D$9:$D$1508,$B8,'Lançamentos'!$B$9:$B$1508,">="&F$5,'Lançamentos'!$B$9:$B$1508,"<"&EDATE(F$5,1))) -> 0 | G8: =IF($B8="",0,SUMIFS('Lançamentos'!$F$9:$F$1508,'Lançamentos'!$D$9:$D$1508,$B8,'Lançamentos'!$B$9:$B$1508,">="&G$5,'Lançamentos'!$B$9:$B$1508,"<"&EDATE(G$5,1))) -> 0 | H8: =IF($B8="",0,SUMIFS('Lançamentos'!$F$9:$F$1508,'Lançamentos'!$D$9:$D$1508,$B8,'Lançamentos'!$B$9:$B$1508,">="&H$5,'Lançamentos'!$B$9:$B$1508,"<"&EDATE(H$5,1))) -> 0 | I8: =IF($B8="",0,SUMIFS('Lançamentos'!$F$9:$F$1508,'Lançamentos'!$D$9:$D$1508,$B8,'Lançamentos'!$B$9:$B$1508,">="&I$5,'Lançamentos'!$B$9:$B$1508,"<"&EDATE(I$5,1))) -> 0 | J8: =IF($B8="",0,SUMIFS('Lançamentos'!$F$9:$F$1508,'Lançamentos'!$D$9:$D$1508,$B8,'Lançamentos'!$B$9:$B$1508,">="&J$5,'Lançamentos'!$B$9:$B$1508,"<"&EDATE(J$5,1))) -> 0 | ... N8: =IF($B8="",0,SUMIFS('Lançamentos'!$F$9:$F$1508,'Lançamentos'!$D$9:$D$1508,$B8,'Lançamentos'!$B$9:$B$1508,">="&N$5,'Lançamentos'!$B$9:$B$1508,"<"&EDATE(N$5,1))) -> 0 | O8: =SUM(C8:N8) -> 0 | P8: =IFERROR(O8/'Dados'!$C$9,0) -> 0
B9: =IF('Config'!$E$7="","",'Config'!$E$7) -> Renda extra | C9: =IF($B9="",0,SUMIFS('Lançamentos'!$F$9:$F$1508,'Lançamentos'!$D$9:$D$1508,$B9,'Lançamentos'!$B$9:$B$1508,">="&C$5,'Lançamentos'!$B$9:$B$1508,"<"&EDATE(C$5,1))) -> 0 | D9: =IF($B9="",0,SUMIFS('Lançamentos'!$F$9:$F$1508,'Lançamentos'!$D$9:$D$1508,$B9,'Lançamentos'!$B$9:$B$1508,">="&D$5,'Lançamentos'!$B$9:$B$1508,"<"&EDATE(D$5,1))) -> 0 | E9: =IF($B9="",0,SUMIFS('Lançamentos'!$F$9:$F$1508,'Lançamentos'!$D$9:$D$1508,$B9,'Lançamentos'!$B$9:$B$1508,">="&E$5,'Lançamentos'!$B$9:$B$1508,"<"&EDATE(E$5,1))) -> 0 | F9: =IF($B9="",0,SUMIFS('Lançamentos'!$F$9:$F$1508,'Lançamentos'!$D$9:$D$1508,$B9,'Lançamentos'!$B$9:$B$1508,">="&F$5,'Lançamentos'!$B$9:$B$1508,"<"&EDATE(F$5,1))) -> 0 | G9: =IF($B9="",0,SUMIFS('Lançamentos'!$F$9:$F$1508,'Lançamentos'!$D$9:$D$1508,$B9,'Lançamentos'!$B$9:$B$1508,">="&G$5,'Lançamentos'!$B$9:$B$1508,"<"&EDATE(G$5,1))) -> 0 | H9: =IF($B9="",0,SUMIFS('Lançamentos'!$F$9:$F$1508,'Lançamentos'!$D$9:$D$1508,$B9,'Lançamentos'!$B$9:$B$1508,">="&H$5,'Lançamentos'!$B$9:$B$1508,"<"&EDATE(H$5,1))) -> 0 | I9: =IF($B9="",0,SUMIFS('Lançamentos'!$F$9:$F$1508,'Lançamentos'!$D$9:$D$1508,$B9,'Lançamentos'!$B$9:$B$1508,">="&I$5,'Lançamentos'!$B$9:$B$1508,"<"&EDATE(I$5,1))) -> 0 | J9: =IF($B9="",0,SUMIFS('Lançamentos'!$F$9:$F$1508,'Lançamentos'!$D$9:$D$1508,$B9,'Lançamentos'!$B$9:$B$1508,">="&J$5,'Lançamentos'!$B$9:$B$1508,"<"&EDATE(J$5,1))) -> 0 | ... N9: =IF($B9="",0,SUMIFS('Lançamentos'!$F$9:$F$1508,'Lançamentos'!$D$9:$D$1508,$B9,'Lançamentos'!$B$9:$B$1508,">="&N$5,'Lançamentos'!$B$9:$B$1508,"<"&EDATE(N$5,1))) -> 0 | O9: =SUM(C9:N9) -> 0 | P9: =IFERROR(O9/'Dados'!$C$9,0) -> 0
B10: =IF('Config'!$E$8="","",'Config'!$E$8) -> Rendimentos de investimentos | C10: =IF($B10="",0,SUMIFS('Lançamentos'!$F$9:$F$1508,'Lançamentos'!$D$9:$D$1508,$B10,'Lançamentos'!$B$9:$B$1508,">="&C$5,'Lançamentos'!$B$9:$B$1508,"<"&EDATE(C$5,1))) -> 0 | D10: =IF($B10="",0,SUMIFS('Lançamentos'!$F$9:$F$1508,'Lançamentos'!$D$9:$D$1508,$B10,'Lançamentos'!$B$9:$B$1508,">="&D$5,'Lançamentos'!$B$9:$B$1508,"<"&EDATE(D$5,1))) -> 0 | E10: =IF($B10="",0,SUMIFS('Lançamentos'!$F$9:$F$1508,'Lançamentos'!$D$9:$D$1508,$B10,'Lançamentos'!$B$9:$B$1508,">="&E$5,'Lançamentos'!$B$9:$B$1508,"<"&EDATE(E$5,1))) -> 0 | F10: =IF($B10="",0,SUMIFS('Lançamentos'!$F$9:$F$1508,'Lançamentos'!$D$9:$D$1508,$B10,'Lançamentos'!$B$9:$B$1508,">="&F$5,'Lançamentos'!$B$9:$B$1508,"<"&EDATE(F$5,1))) -> 0 | G10: =IF($B10="",0,SUMIFS('Lançamentos'!$F$9:$F$1508,'Lançamentos'!$D$9:$D$1508,$B10,'Lançamentos'!$B$9:$B$1508,">="&G$5,'Lançamentos'!$B$9:$B$1508,"<"&EDATE(G$5,1))) -> 0 | H10: =IF($B10="",0,SUMIFS('Lançamentos'!$F$9:$F$1508,'Lançamentos'!$D$9:$D$1508,$B10,'Lançamentos'!$B$9:$B$1508,">="&H$5,'Lançamentos'!$B$9:$B$1508,"<"&EDATE(H$5,1))) -> 0 | I10: =IF($B10="",0,SUMIFS('Lançamentos'!$F$9:$F$1508,'Lançamentos'!$D$9:$D$1508,$B10,'Lançamentos'!$B$9:$B$1508,">="&I$5,'Lançamentos'!$B$9:$B$1508,"<"&EDATE(I$5,1))) -> 0 | J10: =IF($B10="",0,SUMIFS('Lançamentos'!$F$9:$F$1508,'Lançamentos'!$D$9:$D$1508,$B10,'Lançamentos'!$B$9:$B$1508,">="&J$5,'Lançamentos'!$B$9:$B$1508,"<"&EDATE(J$5,1))) -> 0 | ... N10: =IF($B10="",0,SUMIFS('Lançamentos'!$F$9:$F$1508,'Lançamentos'!$D$9:$D$1508,$B10,'Lançamentos'!$B$9:$B$1508,">="&N$5,'Lançamentos'!$B$9:$B$1508,"<"&EDATE(N$5,1))) -> 0 | O10: =SUM(C10:N10) -> 0 | P10: =IFERROR(O10/'Dados'!$C$9,0) -> 0
B11: =IF('Config'!$E$9="","",'Config'!$E$9) -> 13º e bônus | C11: =IF($B11="",0,SUMIFS('Lançamentos'!$F$9:$F$1508,'Lançamentos'!$D$9:$D$1508,$B11,'Lançamentos'!$B$9:$B$1508,">="&C$5,'Lançamentos'!$B$9:$B$1508,"<"&EDATE(C$5,1))) -> 0 | D11: =IF($B11="",0,SUMIFS('Lançamentos'!$F$9:$F$1508,'Lançamentos'!$D$9:$D$1508,$B11,'Lançamentos'!$B$9:$B$1508,">="&D$5,'Lançamentos'!$B$9:$B$1508,"<"&EDATE(D$5,1))) -> 0 | E11: =IF($B11="",0,SUMIFS('Lançamentos'!$F$9:$F$1508,'Lançamentos'!$D$9:$D$1508,$B11,'Lançamentos'!$B$9:$B$1508,">="&E$5,'Lançamentos'!$B$9:$B$1508,"<"&EDATE(E$5,1))) -> 0 | F11: =IF($B11="",0,SUMIFS('Lançamentos'!$F$9:$F$1508,'Lançamentos'!$D$9:$D$1508,$B11,'Lançamentos'!$B$9:$B$1508,">="&F$5,'Lançamentos'!$B$9:$B$1508,"<"&EDATE(F$5,1))) -> 0 | G11: =IF($B11="",0,SUMIFS('Lançamentos'!$F$9:$F$1508,'Lançamentos'!$D$9:$D$1508,$B11,'Lançamentos'!$B$9:$B$1508,">="&G$5,'Lançamentos'!$B$9:$B$1508,"<"&EDATE(G$5,1))) -> 0 | H11: =IF($B11="",0,SUMIFS('Lançamentos'!$F$9:$F$1508,'Lançamentos'!$D$9:$D$1508,$B11,'Lançamentos'!$B$9:$B$1508,">="&H$5,'Lançamentos'!$B$9:$B$1508,"<"&EDATE(H$5,1))) -> 0 | I11: =IF($B11="",0,SUMIFS('Lançamentos'!$F$9:$F$1508,'Lançamentos'!$D$9:$D$1508,$B11,'Lançamentos'!$B$9:$B$1508,">="&I$5,'Lançamentos'!$B$9:$B$1508,"<"&EDATE(I$5,1))) -> 0 | J11: =IF($B11="",0,SUMIFS('Lançamentos'!$F$9:$F$1508,'Lançamentos'!$D$9:$D$1508,$B11,'Lançamentos'!$B$9:$B$1508,">="&J$5,'Lançamentos'!$B$9:$B$1508,"<"&EDATE(J$5,1))) -> 0 | ... N11: =IF($B11="",0,SUMIFS('Lançamentos'!$F$9:$F$1508,'Lançamentos'!$D$9:$D$1508,$B11,'Lançamentos'!$B$9:$B$1508,">="&N$5,'Lançamentos'!$B$9:$B$1508,"<"&EDATE(N$5,1))) -> 0 | O11: =SUM(C11:N11) -> 0 | P11: =IFERROR(O11/'Dados'!$C$9,0) -> 0
B12: =IF('Config'!$E$10="","",'Config'!$E$10) -> Reembolsos | C12: =IF($B12="",0,SUMIFS('Lançamentos'!$F$9:$F$1508,'Lançamentos'!$D$9:$D$1508,$B12,'Lançamentos'!$B$9:$B$1508,">="&C$5,'Lançamentos'!$B$9:$B$1508,"<"&EDATE(C$5,1))) -> 0 | D12: =IF($B12="",0,SUMIFS('Lançamentos'!$F$9:$F$1508,'Lançamentos'!$D$9:$D$1508,$B12,'Lançamentos'!$B$9:$B$1508,">="&D$5,'Lançamentos'!$B$9:$B$1508,"<"&EDATE(D$5,1))) -> 0 | E12: =IF($B12="",0,SUMIFS('Lançamentos'!$F$9:$F$1508,'Lançamentos'!$D$9:$D$1508,$B12,'Lançamentos'!$B$9:$B$1508,">="&E$5,'Lançamentos'!$B$9:$B$1508,"<"&EDATE(E$5,1))) -> 0 | F12: =IF($B12="",0,SUMIFS('Lançamentos'!$F$9:$F$1508,'Lançamentos'!$D$9:$D$1508,$B12,'Lançamentos'!$B$9:$B$1508,">="&F$5,'Lançamentos'!$B$9:$B$1508,"<"&EDATE(F$5,1))) -> 0 | G12: =IF($B12="",0,SUMIFS('Lançamentos'!$F$9:$F$1508,'Lançamentos'!$D$9:$D$1508,$B12,'Lançamentos'!$B$9:$B$1508,">="&G$5,'Lançamentos'!$B$9:$B$1508,"<"&EDATE(G$5,1))) -> 0 | H12: =IF($B12="",0,SUMIFS('Lançamentos'!$F$9:$F$1508,'Lançamentos'!$D$9:$D$1508,$B12,'Lançamentos'!$B$9:$B$1508,">="&H$5,'Lançamentos'!$B$9:$B$1508,"<"&EDATE(H$5,1))) -> 0 | I12: =IF($B12="",0,SUMIFS('Lançamentos'!$F$9:$F$1508,'Lançamentos'!$D$9:$D$1508,$B12,'Lançamentos'!$B$9:$B$1508,">="&I$5,'Lançamentos'!$B$9:$B$1508,"<"&EDATE(I$5,1))) -> 0 | J12: =IF($B12="",0,SUMIFS('Lançamentos'!$F$9:$F$1508,'Lançamentos'!$D$9:$D$1508,$B12,'Lançamentos'!$B$9:$B$1508,">="&J$5,'Lançamentos'!$B$9:$B$1508,"<"&EDATE(J$5,1))) -> 0 | ... N12: =IF($B12="",0,SUMIFS('Lançamentos'!$F$9:$F$1508,'Lançamentos'!$D$9:$D$1508,$B12,'Lançamentos'!$B$9:$B$1508,">="&N$5,'Lançamentos'!$B$9:$B$1508,"<"&EDATE(N$5,1))) -> 0 | O12: =SUM(C12:N12) -> 0 | P12: =IFERROR(O12/'Dados'!$C$9,0) -> 0
B13: =IF('Config'!$E$11="","",'Config'!$E$11) -> Aluguéis recebidos | C13: =IF($B13="",0,SUMIFS('Lançamentos'!$F$9:$F$1508,'Lançamentos'!$D$9:$D$1508,$B13,'Lançamentos'!$B$9:$B$1508,">="&C$5,'Lançamentos'!$B$9:$B$1508,"<"&EDATE(C$5,1))) -> 0 | D13: =IF($B13="",0,SUMIFS('Lançamentos'!$F$9:$F$1508,'Lançamentos'!$D$9:$D$1508,$B13,'Lançamentos'!$B$9:$B$1508,">="&D$5,'Lançamentos'!$B$9:$B$1508,"<"&EDATE(D$5,1))) -> 0 | E13: =IF($B13="",0,SUMIFS('Lançamentos'!$F$9:$F$1508,'Lançamentos'!$D$9:$D$1508,$B13,'Lançamentos'!$B$9:$B$1508,">="&E$5,'Lançamentos'!$B$9:$B$1508,"<"&EDATE(E$5,1))) -> 0 | F13: =IF($B13="",0,SUMIFS('Lançamentos'!$F$9:$F$1508,'Lançamentos'!$D$9:$D$1508,$B13,'Lançamentos'!$B$9:$B$1508,">="&F$5,'Lançamentos'!$B$9:$B$1508,"<"&EDATE(F$5,1))) -> 0 | G13: =IF($B13="",0,SUMIFS('Lançamentos'!$F$9:$F$1508,'Lançamentos'!$D$9:$D$1508,$B13,'Lançamentos'!$B$9:$B$1508,">="&G$5,'Lançamentos'!$B$9:$B$1508,"<"&EDATE(G$5,1))) -> 0 | H13: =IF($B13="",0,SUMIFS('Lançamentos'!$F$9:$F$1508,'Lançamentos'!$D$9:$D$1508,$B13,'Lançamentos'!$B$9:$B$1508,">="&H$5,'Lançamentos'!$B$9:$B$1508,"<"&EDATE(H$5,1))) -> 0 | I13: =IF($B13="",0,SUMIFS('Lançamentos'!$F$9:$F$1508,'Lançamentos'!$D$9:$D$1508,$B13,'Lançamentos'!$B$9:$B$1508,">="&I$5,'Lançamentos'!$B$9:$B$1508,"<"&EDATE(I$5,1))) -> 0 | J13: =IF($B13="",0,SUMIFS('Lançamentos'!$F$9:$F$1508,'Lançamentos'!$D$9:$D$1508,$B13,'Lançamentos'!$B$9:$B$1508,">="&J$5,'Lançamentos'!$B$9:$B$1508,"<"&EDATE(J$5,1))) -> 0 | ... N13: =IF($B13="",0,SUMIFS('Lançamentos'!$F$9:$F$1508,'Lançamentos'!$D$9:$D$1508,$B13,'Lançamentos'!$B$9:$B$1508,">="&N$5,'Lançamentos'!$B$9:$B$1508,"<"&EDATE(N$5,1))) -> 0 | O13: =SUM(C13:N13) -> 0 | P13: =IFERROR(O13/'Dados'!$C$9,0) -> 0
B14: =IF('Config'!$E$12="","",'Config'!$E$12) -> Presentes recebidos | C14: =IF($B14="",0,SUMIFS('Lançamentos'!$F$9:$F$1508,'Lançamentos'!$D$9:$D$1508,$B14,'Lançamentos'!$B$9:$B$1508,">="&C$5,'Lançamentos'!$B$9:$B$1508,"<"&EDATE(C$5,1))) -> 0 | D14: =IF($B14="",0,SUMIFS('Lançamentos'!$F$9:$F$1508,'Lançamentos'!$D$9:$D$1508,$B14,'Lançamentos'!$B$9:$B$1508,">="&D$5,'Lançamentos'!$B$9:$B$1508,"<"&EDATE(D$5,1))) -> 0 | E14: =IF($B14="",0,SUMIFS('Lançamentos'!$F$9:$F$1508,'Lançamentos'!$D$9:$D$1508,$B14,'Lançamentos'!$B$9:$B$1508,">="&E$5,'Lançamentos'!$B$9:$B$1508,"<"&EDATE(E$5,1))) -> 0 | F14: =IF($B14="",0,SUMIFS('Lançamentos'!$F$9:$F$1508,'Lançamentos'!$D$9:$D$1508,$B14,'Lançamentos'!$B$9:$B$1508,">="&F$5,'Lançamentos'!$B$9:$B$1508,"<"&EDATE(F$5,1))) -> 0 | G14: =IF($B14="",0,SUMIFS('Lançamentos'!$F$9:$F$1508,'Lançamentos'!$D$9:$D$1508,$B14,'Lançamentos'!$B$9:$B$1508,">="&G$5,'Lançamentos'!$B$9:$B$1508,"<"&EDATE(G$5,1))) -> 0 | H14: =IF($B14="",0,SUMIFS('Lançamentos'!$F$9:$F$1508,'Lançamentos'!$D$9:$D$1508,$B14,'Lançamentos'!$B$9:$B$1508,">="&H$5,'Lançamentos'!$B$9:$B$1508,"<"&EDATE(H$5,1))) -> 0 | I14: =IF($B14="",0,SUMIFS('Lançamentos'!$F$9:$F$1508,'Lançamentos'!$D$9:$D$1508,$B14,'Lançamentos'!$B$9:$B$1508,">="&I$5,'Lançamentos'!$B$9:$B$1508,"<"&EDATE(I$5,1))) -> 0 | J14: =IF($B14="",0,SUMIFS('Lançamentos'!$F$9:$F$1508,'Lançamentos'!$D$9:$D$1508,$B14,'Lançamentos'!$B$9:$B$1508,">="&J$5,'Lançamentos'!$B$9:$B$1508,"<"&EDATE(J$5,1))) -> 0 | ... N14: =IF($B14="",0,SUMIFS('Lançamentos'!$F$9:$F$1508,'Lançamentos'!$D$9:$D$1508,$B14,'Lançamentos'!$B$9:$B$1508,">="&N$5,'Lançamentos'!$B$9:$B$1508,"<"&EDATE(N$5,1))) -> 0 | O14: =SUM(C14:N14) -> 0 | P14: =IFERROR(O14/'Dados'!$C$9,0) -> 0
B15: =IF('Config'!$E$13="","",'Config'!$E$13) -> Outras entradas | C15: =IF($B15="",0,SUMIFS('Lançamentos'!$F$9:$F$1508,'Lançamentos'!$D$9:$D$1508,$B15,'Lançamentos'!$B$9:$B$1508,">="&C$5,'Lançamentos'!$B$9:$B$1508,"<"&EDATE(C$5,1))) -> 0 | D15: =IF($B15="",0,SUMIFS('Lançamentos'!$F$9:$F$1508,'Lançamentos'!$D$9:$D$1508,$B15,'Lançamentos'!$B$9:$B$1508,">="&D$5,'Lançamentos'!$B$9:$B$1508,"<"&EDATE(D$5,1))) -> 0 | E15: =IF($B15="",0,SUMIFS('Lançamentos'!$F$9:$F$1508,'Lançamentos'!$D$9:$D$1508,$B15,'Lançamentos'!$B$9:$B$1508,">="&E$5,'Lançamentos'!$B$9:$B$1508,"<"&EDATE(E$5,1))) -> 0 | F15: =IF($B15="",0,SUMIFS('Lançamentos'!$F$9:$F$1508,'Lançamentos'!$D$9:$D$1508,$B15,'Lançamentos'!$B$9:$B$1508,">="&F$5,'Lançamentos'!$B$9:$B$1508,"<"&EDATE(F$5,1))) -> 0 | G15: =IF($B15="",0,SUMIFS('Lançamentos'!$F$9:$F$1508,'Lançamentos'!$D$9:$D$1508,$B15,'Lançamentos'!$B$9:$B$1508,">="&G$5,'Lançamentos'!$B$9:$B$1508,"<"&EDATE(G$5,1))) -> 0 | H15: =IF($B15="",0,SUMIFS('Lançamentos'!$F$9:$F$1508,'Lançamentos'!$D$9:$D$1508,$B15,'Lançamentos'!$B$9:$B$1508,">="&H$5,'Lançamentos'!$B$9:$B$1508,"<"&EDATE(H$5,1))) -> 0 | I15: =IF($B15="",0,SUMIFS('Lançamentos'!$F$9:$F$1508,'Lançamentos'!$D$9:$D$1508,$B15,'Lançamentos'!$B$9:$B$1508,">="&I$5,'Lançamentos'!$B$9:$B$1508,"<"&EDATE(I$5,1))) -> 0 | J15: =IF($B15="",0,SUMIFS('Lançamentos'!$F$9:$F$1508,'Lançamentos'!$D$9:$D$1508,$B15,'Lançamentos'!$B$9:$B$1508,">="&J$5,'Lançamentos'!$B$9:$B$1508,"<"&EDATE(J$5,1))) -> 0 | ... N15: =IF($B15="",0,SUMIFS('Lançamentos'!$F$9:$F$1508,'Lançamentos'!$D$9:$D$1508,$B15,'Lançamentos'!$B$9:$B$1508,">="&N$5,'Lançamentos'!$B$9:$B$1508,"<"&EDATE(N$5,1))) -> 0 | O15: =SUM(C15:N15) -> 0 | P15: =IFERROR(O15/'Dados'!$C$9,0) -> 0
B16: Total de entradas | C16: =SUM(C8:C15) -> 0 | D16: =SUM(D8:D15) -> 0 | E16: =SUM(E8:E15) -> 0 | F16: =SUM(F8:F15) -> 0 | G16: =SUM(G8:G15) -> 0 | H16: =SUM(H8:H15) -> 0 | I16: =SUM(I8:I15) -> 0 | J16: =SUM(J8:J15) -> 0 | ... P16: =SUM(P8:P15) -> 0
B17: ▼ SAÍDAS
B18: =IF('Config'!$G$6="","",'Config'!$G$6) -> Moradia | C18: =IF($B18="",0,SUMIFS('Lançamentos'!$F$9:$F$1508,'Lançamentos'!$D$9:$D$1508,$B18,'Lançamentos'!$B$9:$B$1508,">="&C$5,'Lançamentos'!$B$9:$B$1508,"<"&EDATE(C$5,1))) -> 0 | D18: =IF($B18="",0,SUMIFS('Lançamentos'!$F$9:$F$1508,'Lançamentos'!$D$9:$D$1508,$B18,'Lançamentos'!$B$9:$B$1508,">="&D$5,'Lançamentos'!$B$9:$B$1508,"<"&EDATE(D$5,1))) -> 0 | E18: =IF($B18="",0,SUMIFS('Lançamentos'!$F$9:$F$1508,'Lançamentos'!$D$9:$D$1508,$B18,'Lançamentos'!$B$9:$B$1508,">="&E$5,'Lançamentos'!$B$9:$B$1508,"<"&EDATE(E$5,1))) -> 0 | F18: =IF($B18="",0,SUMIFS('Lançamentos'!$F$9:$F$1508,'Lançamentos'!$D$9:$D$1508,$B18,'Lançamentos'!$B$9:$B$1508,">="&F$5,'Lançamentos'!$B$9:$B$1508,"<"&EDATE(F$5,1))) -> 0 | G18: =IF($B18="",0,SUMIFS('Lançamentos'!$F$9:$F$1508,'Lançamentos'!$D$9:$D$1508,$B18,'Lançamentos'!$B$9:$B$1508,">="&G$5,'Lançamentos'!$B$9:$B$1508,"<"&EDATE(G$5,1))) -> 0 | H18: =IF($B18="",0,SUMIFS('Lançamentos'!$F$9:$F$1508,'Lançamentos'!$D$9:$D$1508,$B18,'Lançamentos'!$B$9:$B$1508,">="&H$5,'Lançamentos'!$B$9:$B$1508,"<"&EDATE(H$5,1))) -> 0 | I18: =IF($B18="",0,SUMIFS('Lançamentos'!$F$9:$F$1508,'Lançamentos'!$D$9:$D$1508,$B18,'Lançamentos'!$B$9:$B$1508,">="&I$5,'Lançamentos'!$B$9:$B$1508,"<"&EDATE(I$5,1))) -> 0 | J18: =IF($B18="",0,SUMIFS('Lançamentos'!$F$9:$F$1508,'Lançamentos'!$D$9:$D$1508,$B18,'Lançamentos'!$B$9:$B$1508,">="&J$5,'Lançamentos'!$B$9:$B$1508,"<"&EDATE(J$5,1))) -> 0 | ... N18: =IF($B18="",0,SUMIFS('Lançamentos'!$F$9:$F$1508,'Lançamentos'!$D$9:$D$1508,$B18,'Lançamentos'!$B$9:$B$1508,">="&N$5,'Lançamentos'!$B$9:$B$1508,"<"&EDATE(N$5,1))) -> 0 | O18: =SUM(C18:N18) -> 0 | P18: =IFERROR(O18/'Dados'!$C$9,0) -> 0 | Q18: =IFERROR(O18/$O$34,0) -> 0
B19: =IF('Config'!$G$7="","",'Config'!$G$7) -> Contas da casa | C19: =IF($B19="",0,SUMIFS('Lançamentos'!$F$9:$F$1508,'Lançamentos'!$D$9:$D$1508,$B19,'Lançamentos'!$B$9:$B$1508,">="&C$5,'Lançamentos'!$B$9:$B$1508,"<"&EDATE(C$5,1))) -> 0 | D19: =IF($B19="",0,SUMIFS('Lançamentos'!$F$9:$F$1508,'Lançamentos'!$D$9:$D$1508,$B19,'Lançamentos'!$B$9:$B$1508,">="&D$5,'Lançamentos'!$B$9:$B$1508,"<"&EDATE(D$5,1))) -> 0 | E19: =IF($B19="",0,SUMIFS('Lançamentos'!$F$9:$F$1508,'Lançamentos'!$D$9:$D$1508,$B19,'Lançamentos'!$B$9:$B$1508,">="&E$5,'Lançamentos'!$B$9:$B$1508,"<"&EDATE(E$5,1))) -> 0 | F19: =IF($B19="",0,SUMIFS('Lançamentos'!$F$9:$F$1508,'Lançamentos'!$D$9:$D$1508,$B19,'Lançamentos'!$B$9:$B$1508,">="&F$5,'Lançamentos'!$B$9:$B$1508,"<"&EDATE(F$5,1))) -> 0 | G19: =IF($B19="",0,SUMIFS('Lançamentos'!$F$9:$F$1508,'Lançamentos'!$D$9:$D$1508,$B19,'Lançamentos'!$B$9:$B$1508,">="&G$5,'Lançamentos'!$B$9:$B$1508,"<"&EDATE(G$5,1))) -> 0 | H19: =IF($B19="",0,SUMIFS('Lançamentos'!$F$9:$F$1508,'Lançamentos'!$D$9:$D$1508,$B19,'Lançamentos'!$B$9:$B$1508,">="&H$5,'Lançamentos'!$B$9:$B$1508,"<"&EDATE(H$5,1))) -> 0 | I19: =IF($B19="",0,SUMIFS('Lançamentos'!$F$9:$F$1508,'Lançamentos'!$D$9:$D$1508,$B19,'Lançamentos'!$B$9:$B$1508,">="&I$5,'Lançamentos'!$B$9:$B$1508,"<"&EDATE(I$5,1))) -> 0 | J19: =IF($B19="",0,SUMIFS('Lançamentos'!$F$9:$F$1508,'Lançamentos'!$D$9:$D$1508,$B19,'Lançamentos'!$B$9:$B$1508,">="&J$5,'Lançamentos'!$B$9:$B$1508,"<"&EDATE(J$5,1))) -> 0 | ... N19: =IF($B19="",0,SUMIFS('Lançamentos'!$F$9:$F$1508,'Lançamentos'!$D$9:$D$1508,$B19,'Lançamentos'!$B$9:$B$1508,">="&N$5,'Lançamentos'!$B$9:$B$1508,"<"&EDATE(N$5,1))) -> 0 | O19: =SUM(C19:N19) -> 0 | P19: =IFERROR(O19/'Dados'!$C$9,0) -> 0 | Q19: =IFERROR(O19/$O$34,0) -> 0
B20: =IF('Config'!$G$8="","",'Config'!$G$8) -> Alimentação | C20: =IF($B20="",0,SUMIFS('Lançamentos'!$F$9:$F$1508,'Lançamentos'!$D$9:$D$1508,$B20,'Lançamentos'!$B$9:$B$1508,">="&C$5,'Lançamentos'!$B$9:$B$1508,"<"&EDATE(C$5,1))) -> 0 | D20: =IF($B20="",0,SUMIFS('Lançamentos'!$F$9:$F$1508,'Lançamentos'!$D$9:$D$1508,$B20,'Lançamentos'!$B$9:$B$1508,">="&D$5,'Lançamentos'!$B$9:$B$1508,"<"&EDATE(D$5,1))) -> 0 | E20: =IF($B20="",0,SUMIFS('Lançamentos'!$F$9:$F$1508,'Lançamentos'!$D$9:$D$1508,$B20,'Lançamentos'!$B$9:$B$1508,">="&E$5,'Lançamentos'!$B$9:$B$1508,"<"&EDATE(E$5,1))) -> 0 | F20: =IF($B20="",0,SUMIFS('Lançamentos'!$F$9:$F$1508,'Lançamentos'!$D$9:$D$1508,$B20,'Lançamentos'!$B$9:$B$1508,">="&F$5,'Lançamentos'!$B$9:$B$1508,"<"&EDATE(F$5,1))) -> 0 | G20: =IF($B20="",0,SUMIFS('Lançamentos'!$F$9:$F$1508,'Lançamentos'!$D$9:$D$1508,$B20,'Lançamentos'!$B$9:$B$1508,">="&G$5,'Lançamentos'!$B$9:$B$1508,"<"&EDATE(G$5,1))) -> 0 | H20: =IF($B20="",0,SUMIFS('Lançamentos'!$F$9:$F$1508,'Lançamentos'!$D$9:$D$1508,$B20,'Lançamentos'!$B$9:$B$1508,">="&H$5,'Lançamentos'!$B$9:$B$1508,"<"&EDATE(H$5,1))) -> 0 | I20: =IF($B20="",0,SUMIFS('Lançamentos'!$F$9:$F$1508,'Lançamentos'!$D$9:$D$1508,$B20,'Lançamentos'!$B$9:$B$1508,">="&I$5,'Lançamentos'!$B$9:$B$1508,"<"&EDATE(I$5,1))) -> 0 | J20: =IF($B20="",0,SUMIFS('Lançamentos'!$F$9:$F$1508,'Lançamentos'!$D$9:$D$1508,$B20,'Lançamentos'!$B$9:$B$1508,">="&J$5,'Lançamentos'!$B$9:$B$1508,"<"&EDATE(J$5,1))) -> 0 | ... N20: =IF($B20="",0,SUMIFS('Lançamentos'!$F$9:$F$1508,'Lançamentos'!$D$9:$D$1508,$B20,'Lançamentos'!$B$9:$B$1508,">="&N$5,'Lançamentos'!$B$9:$B$1508,"<"&EDATE(N$5,1))) -> 0 | O20: =SUM(C20:N20) -> 0 | P20: =IFERROR(O20/'Dados'!$C$9,0) -> 0 | Q20: =IFERROR(O20/$O$34,0) -> 0
B21: =IF('Config'!$G$9="","",'Config'!$G$9) -> Transporte | C21: =IF($B21="",0,SUMIFS('Lançamentos'!$F$9:$F$1508,'Lançamentos'!$D$9:$D$1508,$B21,'Lançamentos'!$B$9:$B$1508,">="&C$5,'Lançamentos'!$B$9:$B$1508,"<"&EDATE(C$5,1))) -> 0 | D21: =IF($B21="",0,SUMIFS('Lançamentos'!$F$9:$F$1508,'Lançamentos'!$D$9:$D$1508,$B21,'Lançamentos'!$B$9:$B$1508,">="&D$5,'Lançamentos'!$B$9:$B$1508,"<"&EDATE(D$5,1))) -> 0 | E21: =IF($B21="",0,SUMIFS('Lançamentos'!$F$9:$F$1508,'Lançamentos'!$D$9:$D$1508,$B21,'Lançamentos'!$B$9:$B$1508,">="&E$5,'Lançamentos'!$B$9:$B$1508,"<"&EDATE(E$5,1))) -> 0 | F21: =IF($B21="",0,SUMIFS('Lançamentos'!$F$9:$F$1508,'Lançamentos'!$D$9:$D$1508,$B21,'Lançamentos'!$B$9:$B$1508,">="&F$5,'Lançamentos'!$B$9:$B$1508,"<"&EDATE(F$5,1))) -> 0 | G21: =IF($B21="",0,SUMIFS('Lançamentos'!$F$9:$F$1508,'Lançamentos'!$D$9:$D$1508,$B21,'Lançamentos'!$B$9:$B$1508,">="&G$5,'Lançamentos'!$B$9:$B$1508,"<"&EDATE(G$5,1))) -> 0 | H21: =IF($B21="",0,SUMIFS('Lançamentos'!$F$9:$F$1508,'Lançamentos'!$D$9:$D$1508,$B21,'Lançamentos'!$B$9:$B$1508,">="&H$5,'Lançamentos'!$B$9:$B$1508,"<"&EDATE(H$5,1))) -> 0 | I21: =IF($B21="",0,SUMIFS('Lançamentos'!$F$9:$F$1508,'Lançamentos'!$D$9:$D$1508,$B21,'Lançamentos'!$B$9:$B$1508,">="&I$5,'Lançamentos'!$B$9:$B$1508,"<"&EDATE(I$5,1))) -> 0 | J21: =IF($B21="",0,SUMIFS('Lançamentos'!$F$9:$F$1508,'Lançamentos'!$D$9:$D$1508,$B21,'Lançamentos'!$B$9:$B$1508,">="&J$5,'Lançamentos'!$B$9:$B$1508,"<"&EDATE(J$5,1))) -> 0 | ... N21: =IF($B21="",0,SUMIFS('Lançamentos'!$F$9:$F$1508,'Lançamentos'!$D$9:$D$1508,$B21,'Lançamentos'!$B$9:$B$1508,">="&N$5,'Lançamentos'!$B$9:$B$1508,"<"&EDATE(N$5,1))) -> 0 | O21: =SUM(C21:N21) -> 0 | P21: =IFERROR(O21/'Dados'!$C$9,0) -> 0 | Q21: =IFERROR(O21/$O$34,0) -> 0
B22: =IF('Config'!$G$10="","",'Config'!$G$10) -> Saúde | C22: =IF($B22="",0,SUMIFS('Lançamentos'!$F$9:$F$1508,'Lançamentos'!$D$9:$D$1508,$B22,'Lançamentos'!$B$9:$B$1508,">="&C$5,'Lançamentos'!$B$9:$B$1508,"<"&EDATE(C$5,1))) -> 0 | D22: =IF($B22="",0,SUMIFS('Lançamentos'!$F$9:$F$1508,'Lançamentos'!$D$9:$D$1508,$B22,'Lançamentos'!$B$9:$B$1508,">="&D$5,'Lançamentos'!$B$9:$B$1508,"<"&EDATE(D$5,1))) -> 0 | E22: =IF($B22="",0,SUMIFS('Lançamentos'!$F$9:$F$1508,'Lançamentos'!$D$9:$D$1508,$B22,'Lançamentos'!$B$9:$B$1508,">="&E$5,'Lançamentos'!$B$9:$B$1508,"<"&EDATE(E$5,1))) -> 0 | F22: =IF($B22="",0,SUMIFS('Lançamentos'!$F$9:$F$1508,'Lançamentos'!$D$9:$D$1508,$B22,'Lançamentos'!$B$9:$B$1508,">="&F$5,'Lançamentos'!$B$9:$B$1508,"<"&EDATE(F$5,1))) -> 0 | G22: =IF($B22="",0,SUMIFS('Lançamentos'!$F$9:$F$1508,'Lançamentos'!$D$9:$D$1508,$B22,'Lançamentos'!$B$9:$B$1508,">="&G$5,'Lançamentos'!$B$9:$B$1508,"<"&EDATE(G$5,1))) -> 0 | H22: =IF($B22="",0,SUMIFS('Lançamentos'!$F$9:$F$1508,'Lançamentos'!$D$9:$D$1508,$B22,'Lançamentos'!$B$9:$B$1508,">="&H$5,'Lançamentos'!$B$9:$B$1508,"<"&EDATE(H$5,1))) -> 0 | I22: =IF($B22="",0,SUMIFS('Lançamentos'!$F$9:$F$1508,'Lançamentos'!$D$9:$D$1508,$B22,'Lançamentos'!$B$9:$B$1508,">="&I$5,'Lançamentos'!$B$9:$B$1508,"<"&EDATE(I$5,1))) -> 0 | J22: =IF($B22="",0,SUMIFS('Lançamentos'!$F$9:$F$1508,'Lançamentos'!$D$9:$D$1508,$B22,'Lançamentos'!$B$9:$B$1508,">="&J$5,'Lançamentos'!$B$9:$B$1508,"<"&EDATE(J$5,1))) -> 0 | ... N22: =IF($B22="",0,SUMIFS('Lançamentos'!$F$9:$F$1508,'Lançamentos'!$D$9:$D$1508,$B22,'Lançamentos'!$B$9:$B$1508,">="&N$5,'Lançamentos'!$B$9:$B$1508,"<"&EDATE(N$5,1))) -> 0 | O22: =SUM(C22:N22) -> 0 | P22: =IFERROR(O22/'Dados'!$C$9,0) -> 0 | Q22: =IFERROR(O22/$O$34,0) -> 0
B23: =IF('Config'!$G$11="","",'Config'!$G$11) -> Educação | C23: =IF($B23="",0,SUMIFS('Lançamentos'!$F$9:$F$1508,'Lançamentos'!$D$9:$D$1508,$B23,'Lançamentos'!$B$9:$B$1508,">="&C$5,'Lançamentos'!$B$9:$B$1508,"<"&EDATE(C$5,1))) -> 0 | D23: =IF($B23="",0,SUMIFS('Lançamentos'!$F$9:$F$1508,'Lançamentos'!$D$9:$D$1508,$B23,'Lançamentos'!$B$9:$B$1508,">="&D$5,'Lançamentos'!$B$9:$B$1508,"<"&EDATE(D$5,1))) -> 0 | E23: =IF($B23="",0,SUMIFS('Lançamentos'!$F$9:$F$1508,'Lançamentos'!$D$9:$D$1508,$B23,'Lançamentos'!$B$9:$B$1508,">="&E$5,'Lançamentos'!$B$9:$B$1508,"<"&EDATE(E$5,1))) -> 0 | F23: =IF($B23="",0,SUMIFS('Lançamentos'!$F$9:$F$1508,'Lançamentos'!$D$9:$D$1508,$B23,'Lançamentos'!$B$9:$B$1508,">="&F$5,'Lançamentos'!$B$9:$B$1508,"<"&EDATE(F$5,1))) -> 0 | G23: =IF($B23="",0,SUMIFS('Lançamentos'!$F$9:$F$1508,'Lançamentos'!$D$9:$D$1508,$B23,'Lançamentos'!$B$9:$B$1508,">="&G$5,'Lançamentos'!$B$9:$B$1508,"<"&EDATE(G$5,1))) -> 0 | H23: =IF($B23="",0,SUMIFS('Lançamentos'!$F$9:$F$1508,'Lançamentos'!$D$9:$D$1508,$B23,'Lançamentos'!$B$9:$B$1508,">="&H$5,'Lançamentos'!$B$9:$B$1508,"<"&EDATE(H$5,1))) -> 0 | I23: =IF($B23="",0,SUMIFS('Lançamentos'!$F$9:$F$1508,'Lançamentos'!$D$9:$D$1508,$B23,'Lançamentos'!$B$9:$B$1508,">="&I$5,'Lançamentos'!$B$9:$B$1508,"<"&EDATE(I$5,1))) -> 0 | J23: =IF($B23="",0,SUMIFS('Lançamentos'!$F$9:$F$1508,'Lançamentos'!$D$9:$D$1508,$B23,'Lançamentos'!$B$9:$B$1508,">="&J$5,'Lançamentos'!$B$9:$B$1508,"<"&EDATE(J$5,1))) -> 0 | ... N23: =IF($B23="",0,SUMIFS('Lançamentos'!$F$9:$F$1508,'Lançamentos'!$D$9:$D$1508,$B23,'Lançamentos'!$B$9:$B$1508,">="&N$5,'Lançamentos'!$B$9:$B$1508,"<"&EDATE(N$5,1))) -> 0 | O23: =SUM(C23:N23) -> 0 | P23: =IFERROR(O23/'Dados'!$C$9,0) -> 0 | Q23: =IFERROR(O23/$O$34,0) -> 0
B24: =IF('Config'!$G$12="","",'Config'!$G$12) -> Lazer | C24: =IF($B24="",0,SUMIFS('Lançamentos'!$F$9:$F$1508,'Lançamentos'!$D$9:$D$1508,$B24,'Lançamentos'!$B$9:$B$1508,">="&C$5,'Lançamentos'!$B$9:$B$1508,"<"&EDATE(C$5,1))) -> 0 | D24: =IF($B24="",0,SUMIFS('Lançamentos'!$F$9:$F$1508,'Lançamentos'!$D$9:$D$1508,$B24,'Lançamentos'!$B$9:$B$1508,">="&D$5,'Lançamentos'!$B$9:$B$1508,"<"&EDATE(D$5,1))) -> 0 | E24: =IF($B24="",0,SUMIFS('Lançamentos'!$F$9:$F$1508,'Lançamentos'!$D$9:$D$1508,$B24,'Lançamentos'!$B$9:$B$1508,">="&E$5,'Lançamentos'!$B$9:$B$1508,"<"&EDATE(E$5,1))) -> 0 | F24: =IF($B24="",0,SUMIFS('Lançamentos'!$F$9:$F$1508,'Lançamentos'!$D$9:$D$1508,$B24,'Lançamentos'!$B$9:$B$1508,">="&F$5,'Lançamentos'!$B$9:$B$1508,"<"&EDATE(F$5,1))) -> 0 | G24: =IF($B24="",0,SUMIFS('Lançamentos'!$F$9:$F$1508,'Lançamentos'!$D$9:$D$1508,$B24,'Lançamentos'!$B$9:$B$1508,">="&G$5,'Lançamentos'!$B$9:$B$1508,"<"&EDATE(G$5,1))) -> 0 | H24: =IF($B24="",0,SUMIFS('Lançamentos'!$F$9:$F$1508,'Lançamentos'!$D$9:$D$1508,$B24,'Lançamentos'!$B$9:$B$1508,">="&H$5,'Lançamentos'!$B$9:$B$1508,"<"&EDATE(H$5,1))) -> 0 | I24: =IF($B24="",0,SUMIFS('Lançamentos'!$F$9:$F$1508,'Lançamentos'!$D$9:$D$1508,$B24,'Lançamentos'!$B$9:$B$1508,">="&I$5,'Lançamentos'!$B$9:$B$1508,"<"&EDATE(I$5,1))) -> 0 | J24: =IF($B24="",0,SUMIFS('Lançamentos'!$F$9:$F$1508,'Lançamentos'!$D$9:$D$1508,$B24,'Lançamentos'!$B$9:$B$1508,">="&J$5,'Lançamentos'!$B$9:$B$1508,"<"&EDATE(J$5,1))) -> 0 | ... N24: =IF($B24="",0,SUMIFS('Lançamentos'!$F$9:$F$1508,'Lançamentos'!$D$9:$D$1508,$B24,'Lançamentos'!$B$9:$B$1508,">="&N$5,'Lançamentos'!$B$9:$B$1508,"<"&EDATE(N$5,1))) -> 0 | O24: =SUM(C24:N24) -> 0 | P24: =IFERROR(O24/'Dados'!$C$9,0) -> 0 | Q24: =IFERROR(O24/$O$34,0) -> 0
B25: =IF('Config'!$G$13="","",'Config'!$G$13) -> Vestuário | C25: =IF($B25="",0,SUMIFS('Lançamentos'!$F$9:$F$1508,'Lançamentos'!$D$9:$D$1508,$B25,'Lançamentos'!$B$9:$B$1508,">="&C$5,'Lançamentos'!$B$9:$B$1508,"<"&EDATE(C$5,1))) -> 0 | D25: =IF($B25="",0,SUMIFS('Lançamentos'!$F$9:$F$1508,'Lançamentos'!$D$9:$D$1508,$B25,'Lançamentos'!$B$9:$B$1508,">="&D$5,'Lançamentos'!$B$9:$B$1508,"<"&EDATE(D$5,1))) -> 0 | E25: =IF($B25="",0,SUMIFS('Lançamentos'!$F$9:$F$1508,'Lançamentos'!$D$9:$D$1508,$B25,'Lançamentos'!$B$9:$B$1508,">="&E$5,'Lançamentos'!$B$9:$B$1508,"<"&EDATE(E$5,1))) -> 0 | F25: =IF($B25="",0,SUMIFS('Lançamentos'!$F$9:$F$1508,'Lançamentos'!$D$9:$D$1508,$B25,'Lançamentos'!$B$9:$B$1508,">="&F$5,'Lançamentos'!$B$9:$B$1508,"<"&EDATE(F$5,1))) -> 0 | G25: =IF($B25="",0,SUMIFS('Lançamentos'!$F$9:$F$1508,'Lançamentos'!$D$9:$D$1508,$B25,'Lançamentos'!$B$9:$B$1508,">="&G$5,'Lançamentos'!$B$9:$B$1508,"<"&EDATE(G$5,1))) -> 0 | H25: =IF($B25="",0,SUMIFS('Lançamentos'!$F$9:$F$1508,'Lançamentos'!$D$9:$D$1508,$B25,'Lançamentos'!$B$9:$B$1508,">="&H$5,'Lançamentos'!$B$9:$B$1508,"<"&EDATE(H$5,1))) -> 0 | I25: =IF($B25="",0,SUMIFS('Lançamentos'!$F$9:$F$1508,'Lançamentos'!$D$9:$D$1508,$B25,'Lançamentos'!$B$9:$B$1508,">="&I$5,'Lançamentos'!$B$9:$B$1508,"<"&EDATE(I$5,1))) -> 0 | J25: =IF($B25="",0,SUMIFS('Lançamentos'!$F$9:$F$1508,'Lançamentos'!$D$9:$D$1508,$B25,'Lançamentos'!$B$9:$B$1508,">="&J$5,'Lançamentos'!$B$9:$B$1508,"<"&EDATE(J$5,1))) -> 0 | ... N25: =IF($B25="",0,SUMIFS('Lançamentos'!$F$9:$F$1508,'Lançamentos'!$D$9:$D$1508,$B25,'Lançamentos'!$B$9:$B$1508,">="&N$5,'Lançamentos'!$B$9:$B$1508,"<"&EDATE(N$5,1))) -> 0 | O25: =SUM(C25:N25) -> 0 | P25: =IFERROR(O25/'Dados'!$C$9,0) -> 0 | Q25: =IFERROR(O25/$O$34,0) -> 0
B26: =IF('Config'!$G$14="","",'Config'!$G$14) -> Assinaturas | C26: =IF($B26="",0,SUMIFS('Lançamentos'!$F$9:$F$1508,'Lançamentos'!$D$9:$D$1508,$B26,'Lançamentos'!$B$9:$B$1508,">="&C$5,'Lançamentos'!$B$9:$B$1508,"<"&EDATE(C$5,1))) -> 0 | D26: =IF($B26="",0,SUMIFS('Lançamentos'!$F$9:$F$1508,'Lançamentos'!$D$9:$D$1508,$B26,'Lançamentos'!$B$9:$B$1508,">="&D$5,'Lançamentos'!$B$9:$B$1508,"<"&EDATE(D$5,1))) -> 0 | E26: =IF($B26="",0,SUMIFS('Lançamentos'!$F$9:$F$1508,'Lançamentos'!$D$9:$D$1508,$B26,'Lançamentos'!$B$9:$B$1508,">="&E$5,'Lançamentos'!$B$9:$B$1508,"<"&EDATE(E$5,1))) -> 0 | F26: =IF($B26="",0,SUMIFS('Lançamentos'!$F$9:$F$1508,'Lançamentos'!$D$9:$D$1508,$B26,'Lançamentos'!$B$9:$B$1508,">="&F$5,'Lançamentos'!$B$9:$B$1508,"<"&EDATE(F$5,1))) -> 0 | G26: =IF($B26="",0,SUMIFS('Lançamentos'!$F$9:$F$1508,'Lançamentos'!$D$9:$D$1508,$B26,'Lançamentos'!$B$9:$B$1508,">="&G$5,'Lançamentos'!$B$9:$B$1508,"<"&EDATE(G$5,1))) -> 0 | H26: =IF($B26="",0,SUMIFS('Lançamentos'!$F$9:$F$1508,'Lançamentos'!$D$9:$D$1508,$B26,'Lançamentos'!$B$9:$B$1508,">="&H$5,'Lançamentos'!$B$9:$B$1508,"<"&EDATE(H$5,1))) -> 0 | I26: =IF($B26="",0,SUMIFS('Lançamentos'!$F$9:$F$1508,'Lançamentos'!$D$9:$D$1508,$B26,'Lançamentos'!$B$9:$B$1508,">="&I$5,'Lançamentos'!$B$9:$B$1508,"<"&EDATE(I$5,1))) -> 0 | J26: =IF($B26="",0,SUMIFS('Lançamentos'!$F$9:$F$1508,'Lançamentos'!$D$9:$D$1508,$B26,'Lançamentos'!$B$9:$B$1508,">="&J$5,'Lançamentos'!$B$9:$B$1508,"<"&EDATE(J$5,1))) -> 0 | ... N26: =IF($B26="",0,SUMIFS('Lançamentos'!$F$9:$F$1508,'Lançamentos'!$D$9:$D$1508,$B26,'Lançamentos'!$B$9:$B$1508,">="&N$5,'Lançamentos'!$B$9:$B$1508,"<"&EDATE(N$5,1))) -> 0 | O26: =SUM(C26:N26) -> 0 | P26: =IFERROR(O26/'Dados'!$C$9,0) -> 0 | Q26: =IFERROR(O26/$O$34,0) -> 0
B27: =IF('Config'!$G$15="","",'Config'!$G$15) -> Cuidados pessoais | C27: =IF($B27="",0,SUMIFS('Lançamentos'!$F$9:$F$1508,'Lançamentos'!$D$9:$D$1508,$B27,'Lançamentos'!$B$9:$B$1508,">="&C$5,'Lançamentos'!$B$9:$B$1508,"<"&EDATE(C$5,1))) -> 0 | D27: =IF($B27="",0,SUMIFS('Lançamentos'!$F$9:$F$1508,'Lançamentos'!$D$9:$D$1508,$B27,'Lançamentos'!$B$9:$B$1508,">="&D$5,'Lançamentos'!$B$9:$B$1508,"<"&EDATE(D$5,1))) -> 0 | E27: =IF($B27="",0,SUMIFS('Lançamentos'!$F$9:$F$1508,'Lançamentos'!$D$9:$D$1508,$B27,'Lançamentos'!$B$9:$B$1508,">="&E$5,'Lançamentos'!$B$9:$B$1508,"<"&EDATE(E$5,1))) -> 0 | F27: =IF($B27="",0,SUMIFS('Lançamentos'!$F$9:$F$1508,'Lançamentos'!$D$9:$D$1508,$B27,'Lançamentos'!$B$9:$B$1508,">="&F$5,'Lançamentos'!$B$9:$B$1508,"<"&EDATE(F$5,1))) -> 0 | G27: =IF($B27="",0,SUMIFS('Lançamentos'!$F$9:$F$1508,'Lançamentos'!$D$9:$D$1508,$B27,'Lançamentos'!$B$9:$B$1508,">="&G$5,'Lançamentos'!$B$9:$B$1508,"<"&EDATE(G$5,1))) -> 0 | H27: =IF($B27="",0,SUMIFS('Lançamentos'!$F$9:$F$1508,'Lançamentos'!$D$9:$D$1508,$B27,'Lançamentos'!$B$9:$B$1508,">="&H$5,'Lançamentos'!$B$9:$B$1508,"<"&EDATE(H$5,1))) -> 0 | I27: =IF($B27="",0,SUMIFS('Lançamentos'!$F$9:$F$1508,'Lançamentos'!$D$9:$D$1508,$B27,'Lançamentos'!$B$9:$B$1508,">="&I$5,'Lançamentos'!$B$9:$B$1508,"<"&EDATE(I$5,1))) -> 0 | J27: =IF($B27="",0,SUMIFS('Lançamentos'!$F$9:$F$1508,'Lançamentos'!$D$9:$D$1508,$B27,'Lançamentos'!$B$9:$B$1508,">="&J$5,'Lançamentos'!$B$9:$B$1508,"<"&EDATE(J$5,1))) -> 0 | ... N27: =IF($B27="",0,SUMIFS('Lançamentos'!$F$9:$F$1508,'Lançamentos'!$D$9:$D$1508,$B27,'Lançamentos'!$B$9:$B$1508,">="&N$5,'Lançamentos'!$B$9:$B$1508,"<"&EDATE(N$5,1))) -> 0 | O27: =SUM(C27:N27) -> 0 | P27: =IFERROR(O27/'Dados'!$C$9,0) -> 0 | Q27: =IFERROR(O27/$O$34,0) -> 0
B28: =IF('Config'!$G$16="","",'Config'!$G$16) -> Pets | C28: =IF($B28="",0,SUMIFS('Lançamentos'!$F$9:$F$1508,'Lançamentos'!$D$9:$D$1508,$B28,'Lançamentos'!$B$9:$B$1508,">="&C$5,'Lançamentos'!$B$9:$B$1508,"<"&EDATE(C$5,1))) -> 0 | D28: =IF($B28="",0,SUMIFS('Lançamentos'!$F$9:$F$1508,'Lançamentos'!$D$9:$D$1508,$B28,'Lançamentos'!$B$9:$B$1508,">="&D$5,'Lançamentos'!$B$9:$B$1508,"<"&EDATE(D$5,1))) -> 0 | E28: =IF($B28="",0,SUMIFS('Lançamentos'!$F$9:$F$1508,'Lançamentos'!$D$9:$D$1508,$B28,'Lançamentos'!$B$9:$B$1508,">="&E$5,'Lançamentos'!$B$9:$B$1508,"<"&EDATE(E$5,1))) -> 0 | F28: =IF($B28="",0,SUMIFS('Lançamentos'!$F$9:$F$1508,'Lançamentos'!$D$9:$D$1508,$B28,'Lançamentos'!$B$9:$B$1508,">="&F$5,'Lançamentos'!$B$9:$B$1508,"<"&EDATE(F$5,1))) -> 0 | G28: =IF($B28="",0,SUMIFS('Lançamentos'!$F$9:$F$1508,'Lançamentos'!$D$9:$D$1508,$B28,'Lançamentos'!$B$9:$B$1508,">="&G$5,'Lançamentos'!$B$9:$B$1508,"<"&EDATE(G$5,1))) -> 0 | H28: =IF($B28="",0,SUMIFS('Lançamentos'!$F$9:$F$1508,'Lançamentos'!$D$9:$D$1508,$B28,'Lançamentos'!$B$9:$B$1508,">="&H$5,'Lançamentos'!$B$9:$B$1508,"<"&EDATE(H$5,1))) -> 0 | I28: =IF($B28="",0,SUMIFS('Lançamentos'!$F$9:$F$1508,'Lançamentos'!$D$9:$D$1508,$B28,'Lançamentos'!$B$9:$B$1508,">="&I$5,'Lançamentos'!$B$9:$B$1508,"<"&EDATE(I$5,1))) -> 0 | J28: =IF($B28="",0,SUMIFS('Lançamentos'!$F$9:$F$1508,'Lançamentos'!$D$9:$D$1508,$B28,'Lançamentos'!$B$9:$B$1508,">="&J$5,'Lançamentos'!$B$9:$B$1508,"<"&EDATE(J$5,1))) -> 0 | ... N28: =IF($B28="",0,SUMIFS('Lançamentos'!$F$9:$F$1508,'Lançamentos'!$D$9:$D$1508,$B28,'Lançamentos'!$B$9:$B$1508,">="&N$5,'Lançamentos'!$B$9:$B$1508,"<"&EDATE(N$5,1))) -> 0 | O28: =SUM(C28:N28) -> 0 | P28: =IFERROR(O28/'Dados'!$C$9,0) -> 0 | Q28: =IFERROR(O28/$O$34,0) -> 0
B29: =IF('Config'!$G$17="","",'Config'!$G$17) -> Presentes e doações | C29: =IF($B29="",0,SUMIFS('Lançamentos'!$F$9:$F$1508,'Lançamentos'!$D$9:$D$1508,$B29,'Lançamentos'!$B$9:$B$1508,">="&C$5,'Lançamentos'!$B$9:$B$1508,"<"&EDATE(C$5,1))) -> 0 | D29: =IF($B29="",0,SUMIFS('Lançamentos'!$F$9:$F$1508,'Lançamentos'!$D$9:$D$1508,$B29,'Lançamentos'!$B$9:$B$1508,">="&D$5,'Lançamentos'!$B$9:$B$1508,"<"&EDATE(D$5,1))) -> 0 | E29: =IF($B29="",0,SUMIFS('Lançamentos'!$F$9:$F$1508,'Lançamentos'!$D$9:$D$1508,$B29,'Lançamentos'!$B$9:$B$1508,">="&E$5,'Lançamentos'!$B$9:$B$1508,"<"&EDATE(E$5,1))) -> 0 | F29: =IF($B29="",0,SUMIFS('Lançamentos'!$F$9:$F$1508,'Lançamentos'!$D$9:$D$1508,$B29,'Lançamentos'!$B$9:$B$1508,">="&F$5,'Lançamentos'!$B$9:$B$1508,"<"&EDATE(F$5,1))) -> 0 | G29: =IF($B29="",0,SUMIFS('Lançamentos'!$F$9:$F$1508,'Lançamentos'!$D$9:$D$1508,$B29,'Lançamentos'!$B$9:$B$1508,">="&G$5,'Lançamentos'!$B$9:$B$1508,"<"&EDATE(G$5,1))) -> 0 | H29: =IF($B29="",0,SUMIFS('Lançamentos'!$F$9:$F$1508,'Lançamentos'!$D$9:$D$1508,$B29,'Lançamentos'!$B$9:$B$1508,">="&H$5,'Lançamentos'!$B$9:$B$1508,"<"&EDATE(H$5,1))) -> 0 | I29: =IF($B29="",0,SUMIFS('Lançamentos'!$F$9:$F$1508,'Lançamentos'!$D$9:$D$1508,$B29,'Lançamentos'!$B$9:$B$1508,">="&I$5,'Lançamentos'!$B$9:$B$1508,"<"&EDATE(I$5,1))) -> 0 | J29: =IF($B29="",0,SUMIFS('Lançamentos'!$F$9:$F$1508,'Lançamentos'!$D$9:$D$1508,$B29,'Lançamentos'!$B$9:$B$1508,">="&J$5,'Lançamentos'!$B$9:$B$1508,"<"&EDATE(J$5,1))) -> 0 | ... N29: =IF($B29="",0,SUMIFS('Lançamentos'!$F$9:$F$1508,'Lançamentos'!$D$9:$D$1508,$B29,'Lançamentos'!$B$9:$B$1508,">="&N$5,'Lançamentos'!$B$9:$B$1508,"<"&EDATE(N$5,1))) -> 0 | O29: =SUM(C29:N29) -> 0 | P29: =IFERROR(O29/'Dados'!$C$9,0) -> 0 | Q29: =IFERROR(O29/$O$34,0) -> 0
B30: =IF('Config'!$G$18="","",'Config'!$G$18) -> Dívidas e financiamentos | C30: =IF($B30="",0,SUMIFS('Lançamentos'!$F$9:$F$1508,'Lançamentos'!$D$9:$D$1508,$B30,'Lançamentos'!$B$9:$B$1508,">="&C$5,'Lançamentos'!$B$9:$B$1508,"<"&EDATE(C$5,1))) -> 0 | D30: =IF($B30="",0,SUMIFS('Lançamentos'!$F$9:$F$1508,'Lançamentos'!$D$9:$D$1508,$B30,'Lançamentos'!$B$9:$B$1508,">="&D$5,'Lançamentos'!$B$9:$B$1508,"<"&EDATE(D$5,1))) -> 0 | E30: =IF($B30="",0,SUMIFS('Lançamentos'!$F$9:$F$1508,'Lançamentos'!$D$9:$D$1508,$B30,'Lançamentos'!$B$9:$B$1508,">="&E$5,'Lançamentos'!$B$9:$B$1508,"<"&EDATE(E$5,1))) -> 0 | F30: =IF($B30="",0,SUMIFS('Lançamentos'!$F$9:$F$1508,'Lançamentos'!$D$9:$D$1508,$B30,'Lançamentos'!$B$9:$B$1508,">="&F$5,'Lançamentos'!$B$9:$B$1508,"<"&EDATE(F$5,1))) -> 0 | G30: =IF($B30="",0,SUMIFS('Lançamentos'!$F$9:$F$1508,'Lançamentos'!$D$9:$D$1508,$B30,'Lançamentos'!$B$9:$B$1508,">="&G$5,'Lançamentos'!$B$9:$B$1508,"<"&EDATE(G$5,1))) -> 0 | H30: =IF($B30="",0,SUMIFS('Lançamentos'!$F$9:$F$1508,'Lançamentos'!$D$9:$D$1508,$B30,'Lançamentos'!$B$9:$B$1508,">="&H$5,'Lançamentos'!$B$9:$B$1508,"<"&EDATE(H$5,1))) -> 0 | I30: =IF($B30="",0,SUMIFS('Lançamentos'!$F$9:$F$1508,'Lançamentos'!$D$9:$D$1508,$B30,'Lançamentos'!$B$9:$B$1508,">="&I$5,'Lançamentos'!$B$9:$B$1508,"<"&EDATE(I$5,1))) -> 0 | J30: =IF($B30="",0,SUMIFS('Lançamentos'!$F$9:$F$1508,'Lançamentos'!$D$9:$D$1508,$B30,'Lançamentos'!$B$9:$B$1508,">="&J$5,'Lançamentos'!$B$9:$B$1508,"<"&EDATE(J$5,1))) -> 0 | ... N30: =IF($B30="",0,SUMIFS('Lançamentos'!$F$9:$F$1508,'Lançamentos'!$D$9:$D$1508,$B30,'Lançamentos'!$B$9:$B$1508,">="&N$5,'Lançamentos'!$B$9:$B$1508,"<"&EDATE(N$5,1))) -> 0 | O30: =SUM(C30:N30) -> 0 | P30: =IFERROR(O30/'Dados'!$C$9,0) -> 0 | Q30: =IFERROR(O30/$O$34,0) -> 0
B31: =IF('Config'!$G$19="","",'Config'!$G$19) -> Reserva e Metas | C31: =IF($B31="",0,SUMIFS('Lançamentos'!$F$9:$F$1508,'Lançamentos'!$D$9:$D$1508,$B31,'Lançamentos'!$B$9:$B$1508,">="&C$5,'Lançamentos'!$B$9:$B$1508,"<"&EDATE(C$5,1))) -> 0 | D31: =IF($B31="",0,SUMIFS('Lançamentos'!$F$9:$F$1508,'Lançamentos'!$D$9:$D$1508,$B31,'Lançamentos'!$B$9:$B$1508,">="&D$5,'Lançamentos'!$B$9:$B$1508,"<"&EDATE(D$5,1))) -> 0 | E31: =IF($B31="",0,SUMIFS('Lançamentos'!$F$9:$F$1508,'Lançamentos'!$D$9:$D$1508,$B31,'Lançamentos'!$B$9:$B$1508,">="&E$5,'Lançamentos'!$B$9:$B$1508,"<"&EDATE(E$5,1))) -> 0 | F31: =IF($B31="",0,SUMIFS('Lançamentos'!$F$9:$F$1508,'Lançamentos'!$D$9:$D$1508,$B31,'Lançamentos'!$B$9:$B$1508,">="&F$5,'Lançamentos'!$B$9:$B$1508,"<"&EDATE(F$5,1))) -> 0 | G31: =IF($B31="",0,SUMIFS('Lançamentos'!$F$9:$F$1508,'Lançamentos'!$D$9:$D$1508,$B31,'Lançamentos'!$B$9:$B$1508,">="&G$5,'Lançamentos'!$B$9:$B$1508,"<"&EDATE(G$5,1))) -> 0 | H31: =IF($B31="",0,SUMIFS('Lançamentos'!$F$9:$F$1508,'Lançamentos'!$D$9:$D$1508,$B31,'Lançamentos'!$B$9:$B$1508,">="&H$5,'Lançamentos'!$B$9:$B$1508,"<"&EDATE(H$5,1))) -> 0 | I31: =IF($B31="",0,SUMIFS('Lançamentos'!$F$9:$F$1508,'Lançamentos'!$D$9:$D$1508,$B31,'Lançamentos'!$B$9:$B$1508,">="&I$5,'Lançamentos'!$B$9:$B$1508,"<"&EDATE(I$5,1))) -> 0 | J31: =IF($B31="",0,SUMIFS('Lançamentos'!$F$9:$F$1508,'Lançamentos'!$D$9:$D$1508,$B31,'Lançamentos'!$B$9:$B$1508,">="&J$5,'Lançamentos'!$B$9:$B$1508,"<"&EDATE(J$5,1))) -> 0 | ... N31: =IF($B31="",0,SUMIFS('Lançamentos'!$F$9:$F$1508,'Lançamentos'!$D$9:$D$1508,$B31,'Lançamentos'!$B$9:$B$1508,">="&N$5,'Lançamentos'!$B$9:$B$1508,"<"&EDATE(N$5,1))) -> 0 | O31: =SUM(C31:N31) -> 0 | P31: =IFERROR(O31/'Dados'!$C$9,0) -> 0 | Q31: =IFERROR(O31/$O$34,0) -> 0
B32: =IF('Config'!$G$20="","",'Config'!$G$20) -> Impostos pessoais | C32: =IF($B32="",0,SUMIFS('Lançamentos'!$F$9:$F$1508,'Lançamentos'!$D$9:$D$1508,$B32,'Lançamentos'!$B$9:$B$1508,">="&C$5,'Lançamentos'!$B$9:$B$1508,"<"&EDATE(C$5,1))) -> 0 | D32: =IF($B32="",0,SUMIFS('Lançamentos'!$F$9:$F$1508,'Lançamentos'!$D$9:$D$1508,$B32,'Lançamentos'!$B$9:$B$1508,">="&D$5,'Lançamentos'!$B$9:$B$1508,"<"&EDATE(D$5,1))) -> 0 | E32: =IF($B32="",0,SUMIFS('Lançamentos'!$F$9:$F$1508,'Lançamentos'!$D$9:$D$1508,$B32,'Lançamentos'!$B$9:$B$1508,">="&E$5,'Lançamentos'!$B$9:$B$1508,"<"&EDATE(E$5,1))) -> 0 | F32: =IF($B32="",0,SUMIFS('Lançamentos'!$F$9:$F$1508,'Lançamentos'!$D$9:$D$1508,$B32,'Lançamentos'!$B$9:$B$1508,">="&F$5,'Lançamentos'!$B$9:$B$1508,"<"&EDATE(F$5,1))) -> 0 | G32: =IF($B32="",0,SUMIFS('Lançamentos'!$F$9:$F$1508,'Lançamentos'!$D$9:$D$1508,$B32,'Lançamentos'!$B$9:$B$1508,">="&G$5,'Lançamentos'!$B$9:$B$1508,"<"&EDATE(G$5,1))) -> 0 | H32: =IF($B32="",0,SUMIFS('Lançamentos'!$F$9:$F$1508,'Lançamentos'!$D$9:$D$1508,$B32,'Lançamentos'!$B$9:$B$1508,">="&H$5,'Lançamentos'!$B$9:$B$1508,"<"&EDATE(H$5,1))) -> 0 | I32: =IF($B32="",0,SUMIFS('Lançamentos'!$F$9:$F$1508,'Lançamentos'!$D$9:$D$1508,$B32,'Lançamentos'!$B$9:$B$1508,">="&I$5,'Lançamentos'!$B$9:$B$1508,"<"&EDATE(I$5,1))) -> 0 | J32: =IF($B32="",0,SUMIFS('Lançamentos'!$F$9:$F$1508,'Lançamentos'!$D$9:$D$1508,$B32,'Lançamentos'!$B$9:$B$1508,">="&J$5,'Lançamentos'!$B$9:$B$1508,"<"&EDATE(J$5,1))) -> 0 | ... N32: =IF($B32="",0,SUMIFS('Lançamentos'!$F$9:$F$1508,'Lançamentos'!$D$9:$D$1508,$B32,'Lançamentos'!$B$9:$B$1508,">="&N$5,'Lançamentos'!$B$9:$B$1508,"<"&EDATE(N$5,1))) -> 0 | O32: =SUM(C32:N32) -> 0 | P32: =IFERROR(O32/'Dados'!$C$9,0) -> 0 | Q32: =IFERROR(O32/$O$34,0) -> 0
